Workbook

Sheet Dashboard
A1: Week 3 | C1: 🏆 ACQL SEASON DASHBOARD
A4: Weekly Standings | I4: Season Leader | K4: Best Week | L4: Average | M4: Winnings | P4: Season Standings
I5: =INDEX(Season!$A$5:$A$39,MATCH(MAX(Season!$T$5:$T$39),Season!$T$5:$T$39,0)) | K5: =_xlfn.XLOOKUP(I5,Season!A5:A39,Season!V5:V39) | L5: =AVERAGE(_xlfn.XLOOKUP(I5,Season!A5:A39,Season!V5:V39)) | M5: =_xlfn.XLOOKUP(I5,Winnings!A5:A39,Winnings!U5:U39)
A6: Rank | B6: Player | C6: Total | D6: Wins | E6: Win % | F6: GB | G6: $ Owe | P6: Rank | Q6: Player | R6: Total | S6: Win % | T6: GB | U6: $ Owed
A7: 1 | B7: =IFERROR(INDEX(_xlfn.SORTBY(INDIRECT("'"&$A$1&"'!$E$10:$E$44"),INDIRECT("'"&$A$1&"'!$B$10:$B$44"),-1),ROWS($B$7:B7)),"") | C7: {=IF(B7="","",INDEX(_xlfn.SORTBY(INDIRECT("'"&$A$1&"'!$B$10:$B$44"),INDIRECT("'"&$A$1&"'!$B$10:$B$44"),-1),ROWS($B$7:B7)))} | D7: {=IF(B7="","",INDEX(_xlfn.SORTBY(INDIRECT("'"&$A$1&"'!$C$10:$C$44"),INDIRECT("'"&$A$1&"'!$B$10:$B$44"),-1),ROWS($B$7:B7)))} | E7: =IF(B7="","",D7/16) | F7: =$C$7-C7 | G7: =IF(B7="","",F7) | I7: Name | J7: Rank | K7: Best Week | L7: Average | M7: Winnings | P7: 1 | Q7: =_xlfn.XLOOKUP(P7,Table2[Rank],Table2[Player]) | R7: {=_xlfn.XLOOKUP(Q7,Table2[Player],Season!$T$5:$T$39)} | S7: =IFERROR(SUM(_xlfn.XLOOKUP(Q7,Table2[Player],Table2[Season Wins]))/SUM(Season!$B$3:$S$3),0) | T7: =$R$7-R7 | U7: =_xlfn.XLOOKUP(Q7,Winnings!$A$5:$A$39,Winnings!$U$5:$U$39)
A8: 2 | B8: =IFERROR(INDEX(_xlfn.SORTBY(INDIRECT("'"&$A$1&"'!$E$10:$E$44"),INDIRECT("'"&$A$1&"'!$B$10:$B$44"),-1),ROWS($B$7:B8)),"") | C8: {=IF(B8="","",INDEX(_xlfn.SORTBY(INDIRECT("'"&$A$1&"'!$B$10:$B$44"),INDIRECT("'"&$A$1&"'!$B$10:$B$44"),-1),ROWS($B$7:B8)))} | D8: {=IF(B8="","",INDEX(_xlfn.SORTBY(INDIRECT("'"&$A$1&"'!$C$10:$C$44"),INDIRECT("'"&$A$1&"'!$B$10:$B$44"),-1),ROWS($B$7:B8)))} | E8: =IF(B8="","",D8/16) | F8: =$C$7-C8 | G8: =IF(B8="","",F8) | I8: Phelpy | J8: =_xlfn.XLOOKUP(I8,Season!$A$5:$A$39,Season!$X$5:$X$39) | K8: =_xlfn.XLOOKUP(I8,Season!$A$5:$A$39,Season!$V$5:$V$39) | L8: =_xlfn.XLOOKUP(I8,Season!$A$5:$A$39,Season!$U$5:$U$39) | M8: =IF(_xlfn.XLOOKUP(I8,Winnings!A5:A39,Winnings!U5:U39)>0,_xlfn.XLOOKUP(I8,Winnings!A5:A39,Winnings!U5:U39),0) | P8: 2 | Q8: =_xlfn.XLOOKUP(P8,Table2[Rank],Table2[Player]) | R8: {=_xlfn.XLOOKUP(Q8,Table2[Player],Season!$T$5:$T$39)} | S8: =IFERROR(SUM(_xlfn.XLOOKUP(Q8,Table2[Player],Table2[Season Wins]))/SUM(Season!$B$3:$S$3),0) | T8: =$R$7-R8 | U8: =_xlfn.XLOOKUP(Q8,Winnings!$A$5:$A$39,Winnings!$U$5:$U$39)
A9: 3 | B9: =IFERROR(INDEX(_xlfn.SORTBY(INDIRECT("'"&$A$1&"'!$E$10:$E$44"),INDIRECT("'"&$A$1&"'!$B$10:$B$44"),-1),ROWS($B$7:B9)),"") | C9: {=IF(B9="","",INDEX(_xlfn.SORTBY(INDIRECT("'"&$A$1&"'!$B$10:$B$44"),INDIRECT("'"&$A$1&"'!$B$10:$B$44"),-1),ROWS($B$7:B9)))} | D9: {=IF(B9="","",INDEX(_xlfn.SORTBY(INDIRECT("'"&$A$1&"'!$C$10:$C$44"),INDIRECT("'"&$A$1&"'!$B$10:$B$44"),-1),ROWS($B$7:B9)))} | E9: =IF(B9="","",D9/16) | F9: =$C$7-C9 | G9: =IF(B9="","",F9) | I9: Line-Pony | J9: =_xlfn.XLOOKUP(I9,Season!$A$5:$A$39,Season!$X$5:$X$39) | K9: =_xlfn.XLOOKUP(I9,Season!$A$5:$A$39,Season!$V$5:$V$39) | L9: =_xlfn.XLOOKUP(I9,Season!$A$5:$A$39,Season!$U$5:$U$39) | M9: =IF(_xlfn.XLOOKUP(I9,Winnings!A6:A40,Winnings!U6:U40)>0,_xlfn.XLOOKUP(I9,Winnings!A6:A40,Winnings!U6:U40),0) | P9: 3 | Q9: =_xlfn.XLOOKUP(P9,Table2[Rank],Table2[Player]) | R9: {=_xlfn.XLOOKUP(Q9,Table2[Player],Season!$T$5:$T$39)} | S9: =IFERROR(SUM(_xlfn.XLOOKUP(Q9,Table2[Player],Table2[Season Wins]))/SUM(Season!$B$3:$S$3),0) | T9: =$R$7-R9 | U9: =_xlfn.XLOOKUP(Q9,Winnings!$A$5:$A$39,Winnings!$U$5:$U$39)
A10: 4 | B10: =IFERROR(INDEX(_xlfn.SORTBY(INDIRECT("'"&$A$1&"'!$E$10:$E$44"),INDIRECT("'"&$A$1&"'!$B$10:$B$44"),-1),ROWS($B$7:B10)),"") | C10: {=IF(B10="","",INDEX(_xlfn.SORTBY(INDIRECT("'"&$A$1&"'!$B$10:$B$44"),INDIRECT("'"&$A$1&"'!$B$10:$B$44"),-1),ROWS($B$7:B10)))} | D10: {=IF(B10="","",INDEX(_xlfn.SORTBY(INDIRECT("'"&$A$1&"'!$C$10:$C$44"),INDIRECT("'"&$A$1&"'!$B$10:$B$44"),-1),ROWS($B$7:B10)))} | E10: =IF(B10="","",D10/16) | F10: =$C$7-C10 | G10: =IF(B10="","",F10) | I10: Phelps Phamily | J10: =_xlfn.XLOOKUP(I10,Season!$A$5:$A$39,Season!$X$5:$X$39) | K10: =_xlfn.XLOOKUP(I10,Season!$A$5:$A$39,Season!$V$5:$V$39) | L10: =_xlfn.XLOOKUP(I10,Season!$A$5:$A$39,Season!$U$5:$U$39) | M10: =IF(_xlfn.XLOOKUP(I10,Winnings!A7:A41,Winnings!U7:U41)>0,_xlfn.XLOOKUP(I10,Winnings!A7:A41,Winnings!U7:U41),0) | P10: 4 | Q10: =_xlfn.XLOOKUP(P10,Table2[Rank],Table2[Player]) | R10: {=_xlfn.XLOOKUP(Q10,Table2[Player],Season!$T$5:$T$39)} | S10: =IFERROR(SUM(_xlfn.XLOOKUP(Q10,Table2[Player],Table2[Season Wins]))/SUM(Season!$B$3:$S$3),0) | T10: =$R$7-R10 | U10: =_xlfn.XLOOKUP(Q10,Winnings!$A$5:$A$39,Winnings!$U$5:$U$39)
A11: 5 | B11: =IFERROR(INDEX(_xlfn.SORTBY(INDIRECT("'"&$A$1&"'!$E$10:$E$44"),INDIRECT("'"&$A$1&"'!$B$10:$B$44"),-1),ROWS($B$7:B11)),"") | C11: {=IF(B11="","",INDEX(_xlfn.SORTBY(INDIRECT("'"&$A$1&"'!$B$10:$B$44"),INDIRECT("'"&$A$1&"'!$B$10:$B$44"),-1),ROWS($B$7:B11)))} | D11: {=IF(B11="","",INDEX(_xlfn.SORTBY(INDIRECT("'"&$A$1&"'!$C$10:$C$44"),INDIRECT("'"&$A$1&"'!$B$10:$B$44"),-1),ROWS($B$7:B11)))} | E11: =IF(B11="","",D11/16) | F11: =$C$7-C11 | G11: =IF(B11="","",F11) | I11: Vonasek Family | J11: =_xlfn.XLOOKUP(I11,Season!$A$5:$A$39,Season!$X$5:$X$39) | K11: =_xlfn.XLOOKUP(I11,Season!$A$5:$A$39,Season!$V$5:$V$39) | L11: =_xlfn.XLOOKUP(I11,Season!$A$5:$A$39,Season!$U$5:$U$39) | M11: =IF(_xlfn.XLOOKUP(I11,Winnings!A8:A42,Winnings!U8:U42)>0,_xlfn.XLOOKUP(I11,Winnings!A8:A42,Winnings!U8:U42),0) | P11: 5 | Q11: =_xlfn.XLOOKUP(P11,Table2[Rank],Table2[Player]) | R11: {=_xlfn.XLOOKUP(Q11,Table2[Player],Season!$T$5:$T$39)} | S11: =IFERROR(SUM(_xlfn.XLOOKUP(Q11,Table2[Player],Table2[Season Wins]))/SUM(Season!$B$3:$S$3),0) | T11: =$R$7-R11 | U11: =_xlfn.XLOOKUP(Q11,Winnings!$A$5:$A$39,Winnings!$U$5:$U$39)
A12: 6 | B12: =IFERROR(INDEX(_xlfn.SORTBY(INDIRECT("'"&$A$1&"'!$E$10:$E$44"),INDIRECT("'"&$A$1&"'!$B$10:$B$44"),-1),ROWS($B$7:B12)),"") | C12: {=IF(B12="","",INDEX(_xlfn.SORTBY(INDIRECT("'"&$A$1&"'!$B$10:$B$44"),INDIRECT("'"&$A$1&"'!$B$10:$B$44"),-1),ROWS($B$7:B12)))} | D12: {=IF(B12="","",INDEX(_xlfn.SORTBY(INDIRECT("'"&$A$1&"'!$C$10:$C$44"),INDIRECT("'"&$A$1&"'!$B$10:$B$44"),-1),ROWS($B$7:B12)))} | E12: =IF(B12="","",D12/16) | F12: =$C$7-C12 | G12: =IF(B12="","",F12) | I12: Samsaunt | J12: =_xlfn.XLOOKUP(I12,Season!$A$5:$A$39,Season!$X$5:$X$39) | K12: =_xlfn.XLOOKUP(I12,Season!$A$5:$A$39,Season!$V$5:$V$39) | L12: =_xlfn.XLOOKUP(I12,Season!$A$5:$A$39,Season!$U$5:$U$39) | M12: =IF(_xlfn.XLOOKUP(I12,Winnings!A9:A43,Winnings!U9:U43)>0,_xlfn.XLOOKUP(I12,Winnings!A9:A43,Winnings!U9:U43),0) | P12: 6 | Q12: =_xlfn.XLOOKUP(P12,Table2[Rank],Table2[Player]) | R12: {=_xlfn.XLOOKUP(Q12,Table2[Player],Season!$T$5:$T$39)} | S12: =IFERROR(SUM(_xlfn.XLOOKUP(Q12,Table2[Player],Table2[Season Wins]))/SUM(Season!$B$3:$S$3),0) | T12: =$R$7-R12 | U12: =_xlfn.XLOOKUP(Q12,Winnings!$A$5:$A$39,Winnings!$U$5:$U$39)
A13: 7 | B13: =IFERROR(INDEX(_xlfn.SORTBY(INDIRECT("'"&$A$1&"'!$E$10:$E$44"),INDIRECT("'"&$A$1&"'!$B$10:$B$44"),-1),ROWS($B$7:B13)),"") | C13: {=IF(B13="","",INDEX(_xlfn.SORTBY(INDIRECT("'"&$A$1&"'!$B$10:$B$44"),INDIRECT("'"&$A$1&"'!$B$10:$B$44"),-1),ROWS($B$7:B13)))} | D13: {=IF(B13="","",INDEX(_xlfn.SORTBY(INDIRECT("'"&$A$1&"'!$C$10:$C$44"),INDIRECT("'"&$A$1&"'!$B$10:$B$44"),-1),ROWS($B$7:B13)))} | E13: =IF(B13="","",D13/16) | F13: =$C$7-C13 | G13: =IF(B13="","",F13) | P13: 7 | Q13: =_xlfn.XLOOKUP(P13,Table2[Rank],Table2[Player]) | R13: {=_xlfn.XLOOKUP(Q13,Table2[Player],Season!$T$5:$T$39)} | S13: =IFERROR(SUM(_xlfn.XLOOKUP(Q13,Table2[Player],Table2[Season Wins]))/SUM(Season!$B$3:$S$3),0) | T13: =$R$7-R13 | U13: =_xlfn.XLOOKUP(Q13,Winnings!$A$5:$A$39,Winnings!$U$5:$U$39)
A14: 8 | B14: =IFERROR(INDEX(_xlfn.SORTBY(INDIRECT("'"&$A$1&"'!$E$10:$E$44"),INDIRECT("'"&$A$1&"'!$B$10:$B$44"),-1),ROWS($B$7:B14)),"") | C14: {=IF(B14="","",INDEX(_xlfn.SORTBY(INDIRECT("'"&$A$1&"'!$B$10:$B$44"),INDIRECT("'"&$A$1&"'!$B$10:$B$44"),-1),ROWS($B$7:B14)))} | D14: {=IF(B14="","",INDEX(_xlfn.SORTBY(INDIRECT("'"&$A$1&"'!$C$10:$C$44"),INDIRECT("'"&$A$1&"'!$B$10:$B$44"),-1),ROWS($B$7:B14)))} | E14: =IF(B14="","",D14/16) | F14: =$C$7-C14 | G14: =IF(B14="","",F14) | I14: Current Week | J14: Column1 | P14: 8 | Q14: =_xlfn.XLOOKUP(P14,Table2[Rank],Table2[Player]) | R14: {=_xlfn.XLOOKUP(Q14,Table2[Player],Season!$T$5:$T$39)} | S14: =IFERROR(SUM(_xlfn.XLOOKUP(Q14,Table2[Player],Table2[Season Wins]))/SUM(Season!$B$3:$S$3),0) | T14: =$R$7-R14 | U14: =_xlfn.XLOOKUP(Q14,Winnings!$A$5:$A$39,Winnings!$U$5:$U$39)
A15: 9 | B15: =IFERROR(INDEX(_xlfn.SORTBY(INDIRECT("'"&$A$1&"'!$E$10:$E$44"),INDIRECT("'"&$A$1&"'!$B$10:$B$44"),-1),ROWS($B$7:B15)),"") | C15: {=IF(B15="","",INDEX(_xlfn.SORTBY(INDIRECT("'"&$A$1&"'!$B$10:$B$44"),INDIRECT("'"&$A$1&"'!$B$10:$B$44"),-1),ROWS($B$7:B15)))} | D15: {=IF(B15="","",INDEX(_xlfn.SORTBY(INDIRECT("'"&$A$1&"'!$C$10:$C$44"),INDIRECT("'"&$A$1&"'!$B$10:$B$44"),-1),ROWS($B$7:B15)))} | E15: =IF(B15="","",D15/16) | F15: =$C$7-C15 | G15: =IF(B15="","",F15) | I15: High Score | J15: =MAX(INDIRECT("'"&$A$1&"'!$B$10:$B$44")) | P15: 9 | Q15: =_xlfn.XLOOKUP(P15,Table2[Rank],Table2[Player]) | R15: {=_xlfn.XLOOKUP(Q15,Table2[Player],Season!$T$5:$T$39)} | S15: =IFERROR(SUM(_xlfn.XLOOKUP(Q15,Table2[Player],Table2[Season Wins]))/SUM(Season!$B$3:$S$3),0) | T15: =$R$7-R15 | U15: =_xlfn.XLOOKUP(Q15,Winnings!$A$5:$A$39,Winnings!$U$5:$U$39)
A16: 10 | B16: =IFERROR(INDEX(_xlfn.SORTBY(INDIRECT("'"&$A$1&"'!$E$10:$E$44"),INDIRECT("'"&$A$1&"'!$B$10:$B$44"),-1),ROWS($B$7:B16)),"") | C16: {=IF(B16="","",INDEX(_xlfn.SORTBY(INDIRECT("'"&$A$1&"'!$B$10:$B$44"),INDIRECT("'"&$A$1&"'!$B$10:$B$44"),-1),ROWS($B$7:B16)))} | D16: {=IF(B16="","",INDEX(_xlfn.SORTBY(INDIRECT("'"&$A$1&"'!$C$10:$C$44"),INDIRECT("'"&$A$1&"'!$B$10:$B$44"),-1),ROWS($B$7:B16)))} | E16: =IF(B16="","",D16/16) | F16: =$C$7-C16 | G16: =IF(B16="","",F16) | I16: Low Score | J16: =_xlfn.MINIFS(INDIRECT("'"&$A$1&"'!$B$10:$B$44"),INDIRECT("'"&$A$1&"'!$B$10:$B$44"),">=0") | P16: 10 | Q16: =_xlfn.XLOOKUP(P16,Table2[Rank],Table2[Player]) | R16: {=_xlfn.XLOOKUP(Q16,Table2[Player],Season!$T$5:$T$39)} | S16: =IFERROR(SUM(_xlfn.XLOOKUP(Q16,Table2[Player],Table2[Season Wins]))/SUM(Season!$B$3:$S$3),0) | T16: =$R$7-R16 | U16: =_xlfn.XLOOKUP(Q16,Winnings!$A$5:$A$39,Winnings!$U$5:$U$39)
A17: 11 | B17: =IFERROR(INDEX(_xlfn.SORTBY(INDIRECT("'"&$A$1&"'!$E$10:$E$44"),INDIRECT("'"&$A$1&"'!$B$10:$B$44"),-1),ROWS($B$7:B17)),"") | C17: {=IF(B17="","",INDEX(_xlfn.SORTBY(INDIRECT("'"&$A$1&"'!$B$10:$B$44"),INDIRECT("'"&$A$1&"'!$B$10:$B$44"),-1),ROWS($B$7:B17)))} | D17: {=IF(B17="","",INDEX(_xlfn.SORTBY(INDIRECT("'"&$A$1&"'!$C$10:$C$44"),INDIRECT("'"&$A$1&"'!$B$10:$B$44"),-1),ROWS($B$7:B17)))} | E17: =IF(B17="","",D17/16) | F17: =$C$7-C17 | G17: =IF(B17="","",F17) | I17: Average | J17: =IFERROR(AVERAGEIF(INDIRECT("'"&$A$1&"'!$B$10:$B$44"),">=0"),0) | P17: 11 | Q17: =_xlfn.XLOOKUP(P17,Table2[Rank],Table2[Player]) | R17: {=_xlfn.XLOOKUP(Q17,Table2[Player],Season!$T$5:$T$39)} | S17: =IFERROR(SUM(_xlfn.XLOOKUP(Q17,Table2[Player],Table2[Season Wins]))/SUM(Season!$B$3:$S$3),0) | T17: =$R$7-R17 | U17: =_xlfn.XLOOKUP(Q17,Winnings!$A$5:$A$39,Winnings!$U$5:$U$39)
A18: 12 | B18: =IFERROR(INDEX(_xlfn.SORTBY(INDIRECT("'"&$A$1&"'!$E$10:$E$44"),INDIRECT("'"&$A$1&"'!$B$10:$B$44"),-1),ROWS($B$7:B18)),"") | C18: {=IF(B18="","",INDEX(_xlfn.SORTBY(INDIRECT("'"&$A$1&"'!$B$10:$B$44"),INDIRECT("'"&$A$1&"'!$B$10:$B$44"),-1),ROWS($B$7:B18)))} | D18: {=IF(B18="","",INDEX(_xlfn.SORTBY(INDIRECT("'"&$A$1&"'!$C$10:$C$44"),INDIRECT("'"&$A$1&"'!$B$10:$B$44"),-1),ROWS($B$7:B18)))} | E18: =IF(B18="","",D18/16) | F18: =$C$7-C18 | G18: =IF(B18="","",F18) | I18: Players Tied 1st | J18: =COUNTIF(INDIRECT("'"&$A$1&"'!$B$10:$B$44"),MAX(INDIRECT("'"&$A$1&"'!$B$10:$B$44"))) | P18: 12 | Q18: =_xlfn.XLOOKUP(P18,Table2[Rank],Table2[Player]) | R18: {=_xlfn.XLOOKUP(Q18,Table2[Player],Season!$T$5:$T$39)} | S18: =IFERROR(SUM(_xlfn.XLOOKUP(Q18,Table2[Player],Table2[Season Wins]))/SUM(Season!$B$3:$S$3),0) | T18: =$R$7-R18 | U18: =_xlfn.XLOOKUP(Q18,Winnings!$A$5:$A$39,Winnings!$U$5:$U$39)
A19: 13 | B19: =IFERROR(INDEX(_xlfn.SORTBY(INDIRECT("'"&$A$1&"'!$E$10:$E$44"),INDIRECT("'"&$A$1&"'!$B$10:$B$44"),-1),ROWS($B$7:B19)),"") | C19: {=IF(B19="","",INDEX(_xlfn.SORTBY(INDIRECT("'"&$A$1&"'!$B$10:$B$44"),INDIRECT("'"&$A$1&"'!$B$10:$B$44"),-1),ROWS($B$7:B19)))} | D19: {=IF(B19="","",INDEX(_xlfn.SORTBY(INDIRECT("'"&$A$1&"'!$C$10:$C$44"),INDIRECT("'"&$A$1&"'!$B$10:$B$44"),-1),ROWS($B$7:B19)))} | E19: =IF(B19="","",D19/16) | F19: =$C$7-C19 | G19: =IF(B19="","",F19) | I19: # Above Average | J19: =COUNTIF(INDIRECT("'"&$A$1&"'!$B$10:$B$44"),">"&AVERAGE(INDIRECT("'"&$A$1&"'!$B$10:$B$44"))) | P19: 13 | Q19: =_xlfn.XLOOKUP(P19,Table2[Rank],Table2[Player]) | R19: {=_xlfn.XLOOKUP(Q19,Table2[Player],Season!$T$5:$T$39)} | S19: =IFERROR(SUM(_xlfn.XLOOKUP(Q19,Table2[Player],Table2[Season Wins]))/SUM(Season!$B$3:$S$3),0) | T19: =$R$7-R19 | U19: =_xlfn.XLOOKUP(Q19,Winnings!$A$5:$A$39,Winnings!$U$5:$U$39)
A20: 14 | B20: =IFERROR(INDEX(_xlfn.SORTBY(INDIRECT("'"&$A$1&"'!$E$10:$E$44"),INDIRECT("'"&$A$1&"'!$B$10:$B$44"),-1),ROWS($B$7:B20)),"") | C20: {=IF(B20="","",INDEX(_xlfn.SORTBY(INDIRECT("'"&$A$1&"'!$B$10:$B$44"),INDIRECT("'"&$A$1&"'!$B$10:$B$44"),-1),ROWS($B$7:B20)))} | D20: {=IF(B20="","",INDEX(_xlfn.SORTBY(INDIRECT("'"&$A$1&"'!$C$10:$C$44"),INDIRECT("'"&$A$1&"'!$B$10:$B$44"),-1),ROWS($B$7:B20)))} | E20: =IF(B20="","",D20/16) | F20: =$C$7-C20 | G20: =IF(B20="","",F20) | I20: Suicides Used | J20: Column1 | P20: 14 | Q20: =_xlfn.XLOOKUP(P20,Table2[Rank],Table2[Player]) | R20: {=_xlfn.XLOOKUP(Q20,Table2[Player],Season!$T$5:$T$39)} | S20: =IFERROR(SUM(_xlfn.XLOOKUP(Q20,Table2[Player],Table2[Season Wins]))/SUM(Season!$B$3:$S$3),0) | T20: =$R$7-R20 | U20: =_xlfn.XLOOKUP(Q20,Winnings!$A$5:$A$39,Winnings!$U$5:$U$39)
A21: 15 | B21: =IFERROR(INDEX(_xlfn.SORTBY(INDIRECT("'"&$A$1&"'!$E$10:$E$44"),INDIRECT("'"&$A$1&"'!$B$10:$B$44"),-1),ROWS($B$7:B21)),"") | C21: {=IF(B21="","",INDEX(_xlfn.SORTBY(INDIRECT("'"&$A$1&"'!$B$10:$B$44"),INDIRECT("'"&$A$1&"'!$B$10:$B$44"),-1),ROWS($B$7:B21)))} | D21: {=IF(B21="","",INDEX(_xlfn.SORTBY(INDIRECT("'"&$A$1&"'!$C$10:$C$44"),INDIRECT("'"&$A$1&"'!$B$10:$B$44"),-1),ROWS($B$7:B21)))} | E21: =IF(B21="","",D21/16) | F21: =$C$7-C21 | G21: =IF(B21="","",F21) | I21: Week 1 | J21: {=_xlfn.IFNA(_xlfn.XLOOKUP("Phelpy",INDIRECT("'"&I21&"'!$e$10:$e$44"),INDIRECT("'"&I21&"'!$y$10:$y$44")),"")} | P21: 15 | Q21: =_xlfn.XLOOKUP(P21,Table2[Rank],Table2[Player]) | R21: {=_xlfn.XLOOKUP(Q21,Table2[Player],Season!$T$5:$T$39)} | S21: =IFERROR(SUM(_xlfn.XLOOKUP(Q21,Table2[Player],Table2[Season Wins]))/SUM(Season!$B$3:$S$3),0) | T21: =$R$7-R21 | U21: =_xlfn.XLOOKUP(Q21,Winnings!$A$5:$A$39,Winnings!$U$5:$U$39)
A22: 16 | B22: =IFERROR(INDEX(_xlfn.SORTBY(INDIRECT("'"&$A$1&"'!$E$10:$E$44"),INDIRECT("'"&$A$1&"'!$B$10:$B$44"),-1),ROWS($B$7:B22)),"") | C22: {=IF(B22="","",INDEX(_xlfn.SORTBY(INDIRECT("'"&$A$1&"'!$B$10:$B$44"),INDIRECT("'"&$A$1&"'!$B$10:$B$44"),-1),ROWS($B$7:B22)))} | D22: {=IF(B22="","",INDEX(_xlfn.SORTBY(INDIRECT("'"&$A$1&"'!$C$10:$C$44"),INDIRECT("'"&$A$1&"'!$B$10:$B$44"),-1),ROWS($B$7:B22)))} | E22: =IF(B22="","",D22/16) | F22: =$C$7-C22 | G22: =IF(B22="","",F22) | I22: Week 2 | J22: {=_xlfn.IFNA(_xlfn.XLOOKUP("Phelpy",INDIRECT("'"&I22&"'!$e$10:$e$44"),INDIRECT("'"&I22&"'!$y$10:$y$44")),"")} | P22: 16 | Q22: =_xlfn.XLOOKUP(P22,Table2[Rank],Table2[Player]) | R22: {=_xlfn.XLOOKUP(Q22,Table2[Player],Season!$T$5:$T$39)} | S22: =IFERROR(SUM(_xlfn.XLOOKUP(Q22,Table2[Player],Table2[Season Wins]))/SUM(Season!$B$3:$S$3),0) | T22: =$R$7-R22 | U22: =_xlfn.XLOOKUP(Q22,Winnings!$A$5:$A$39,Winnings!$U$5:$U$39)
A23: 17 | B23: =IFERROR(INDEX(_xlfn.SORTBY(INDIRECT("'"&$A$1&"'!$E$10:$E$44"),INDIRECT("'"&$A$1&"'!$B$10:$B$44"),-1),ROWS($B$7:B23)),"") | C23: {=IF(B23="","",INDEX(_xlfn.SORTBY(INDIRECT("'"&$A$1&"'!$B$10:$B$44"),INDIRECT("'"&$A$1&"'!$B$10:$B$44"),-1),ROWS($B$7:B23)))} | D23: {=IF(B23="","",INDEX(_xlfn.SORTBY(INDIRECT("'"&$A$1&"'!$C$10:$C$44"),INDIRECT("'"&$A$1&"'!$B$10:$B$44"),-1),ROWS($B$7:B23)))} | E23: =IF(B23="","",D23/16) | F23: =$C$7-C23 | G23: =IF(B23="","",F23) | I23: Week 3 | J23: {=_xlfn.IFNA(_xlfn.XLOOKUP("Phelpy",INDIRECT("'"&I23&"'!$e$10:$e$44"),INDIRECT("'"&I23&"'!$y$10:$y$44")),"")} | P23: 17 | Q23: =_xlfn.XLOOKUP(P23,Table2[Rank],Table2[Player]) | R23: {=_xlfn.XLOOKUP(Q23,Table2[Player],Season!$T$5:$T$39)} | S23: =IFERROR(SUM(_xlfn.XLOOKUP(Q23,Table2[Player],Table2[Season Wins]))/SUM(Season!$B$3:$S$3),0) | T23: =$R$7-R23 | U23: =_xlfn.XLOOKUP(Q23,Winnings!$A$5:$A$39,Winnings!$U$5:$U$39)
A24: 18 | B24: =IFERROR(INDEX(_xlfn.SORTBY(INDIRECT("'"&$A$1&"'!$E$10:$E$44"),INDIRECT("'"&$A$1&"'!$B$10:$B$44"),-1),ROWS($B$7:B24)),"") | C24: {=IF(B24="","",INDEX(_xlfn.SORTBY(INDIRECT("'"&$A$1&"'!$B$10:$B$44"),INDIRECT("'"&$A$1&"'!$B$10:$B$44"),-1),ROWS($B$7:B24)))} | D24: {=IF(B24="","",INDEX(_xlfn.SORTBY(INDIRECT("'"&$A$1&"'!$C$10:$C$44"),INDIRECT("'"&$A$1&"'!$B$10:$B$44"),-1),ROWS($B$7:B24)))} | E24: =IF(B24="","",D24/16) | F24: =$C$7-C24 | G24: =IF(B24="","",F24) | I24: Week 4 | J24: {=_xlfn.IFNA(_xlfn.XLOOKUP("Phelpy",INDIRECT("'"&I24&"'!$e$10:$e$44"),INDIRECT("'"&I24&"'!$y$10:$y$44")),"")} | P24: 18 | Q24: =_xlfn.XLOOKUP(P24,Table2[Rank],Table2[Player]) | R24: {=_xlfn.XLOOKUP(Q24,Table2[Player],Season!$T$5:$T$39)} | S24: =IFERROR(SUM(_xlfn.XLOOKUP(Q24,Table2[Player],Table2[Season Wins]))/SUM(Season!$B$3:$S$3),0) | T24: =$R$7-R24 | U24: =_xlfn.XLOOKUP(Q24,Winnings!$A$5:$A$39,Winnings!$U$5:$U$39)
A25: 19 | B25: =IFERROR(INDEX(_xlfn.SORTBY(INDIRECT("'"&$A$1&"'!$E$10:$E$44"),INDIRECT("'"&$A$1&"'!$B$10:$B$44"),-1),ROWS($B$7:B25)),"") | C25: {=IF(B25="","",INDEX(_xlfn.SORTBY(INDIRECT("'"&$A$1&"'!$B$10:$B$44"),INDIRECT("'"&$A$1&"'!$B$10:$B$44"),-1),ROWS($B$7:B25)))} | D25: {=IF(B25="","",INDEX(_xlfn.SORTBY(INDIRECT("'"&$A$1&"'!$C$10:$C$44"),INDIRECT("'"&$A$1&"'!$B$10:$B$44"),-1),ROWS($B$7:B25)))} | E25: =IF(B25="","",D25/16) | F25: =$C$7-C25 | G25: =IF(B25="","",F25) | I25: Week 5 | J25: {=_xlfn.IFNA(_xlfn.XLOOKUP("Phelpy",INDIRECT("'"&I25&"'!$e$10:$e$44"),INDIRECT("'"&I25&"'!$y$10:$y$44")),"")} | P25: 19 | Q25: =_xlfn.XLOOKUP(P25,Table2[Rank],Table2[Player]) | R25: {=_xlfn.XLOOKUP(Q25,Table2[Player],Season!$T$5:$T$39)} | S25: =IFERROR(SUM(_xlfn.XLOOKUP(Q25,Table2[Player],Table2[Season Wins]))/SUM(Season!$B$3:$S$3),0) | T25: =$R$7-R25 | U25: =_xlfn.XLOOKUP(Q25,Winnings!$A$5:$A$39,Winnings!$U$5:$U$39)
A26: 20 | B26: =IFERROR(INDEX(_xlfn.SORTBY(INDIRECT("'"&$A$1&"'!$E$10:$E$44"),INDIRECT("'"&$A$1&"'!$B$10:$B$44"),-1),ROWS($B$7:B26)),"") | C26: {=IF(B26="","",INDEX(_xlfn.SORTBY(INDIRECT("'"&$A$1&"'!$B$10:$B$44"),INDIRECT("'"&$A$1&"'!$B$10:$B$44"),-1),ROWS($B$7:B26)))} | D26: {=IF(B26="","",INDEX(_xlfn.SORTBY(INDIRECT("'"&$A$1&"'!$C$10:$C$44"),INDIRECT("'"&$A$1&"'!$B$10:$B$44"),-1),ROWS($B$7:B26)))} | E26: =IF(B26="","",D26/16) | F26: =$C$7-C26 | G26: =IF(B26="","",F26) | I26: Week 6 | J26: {=_xlfn.IFNA(_xlfn.XLOOKUP("Phelpy",INDIRECT("'"&I26&"'!$e$10:$e$44"),INDIRECT("'"&I26&"'!$y$10:$y$44")),"")} | P26: 20 | Q26: =_xlfn.XLOOKUP(P26,Table2[Rank],Table2[Player]) | R26: {=_xlfn.XLOOKUP(Q26,Table2[Player],Season!$T$5:$T$39)} | S26: =IFERROR(SUM(_xlfn.XLOOKUP(Q26,Table2[Player],Table2[Season Wins]))/SUM(Season!$B$3:$S$3),0) | T26: =$R$7-R26 | U26: =_xlfn.XLOOKUP(Q26,Winnings!$A$5:$A$39,Winnings!$U$5:$U$39)
A27: 21 | B27: =IFERROR(INDEX(_xlfn.SORTBY(INDIRECT("'"&$A$1&"'!$E$10:$E$44"),INDIRECT("'"&$A$1&"'!$B$10:$B$44"),-1),ROWS($B$7:B27)),"") | C27: {=IF(B27="","",INDEX(_xlfn.SORTBY(INDIRECT("'"&$A$1&"'!$B$10:$B$44"),INDIRECT("'"&$A$1&"'!$B$10:$B$44"),-1),ROWS($B$7:B27)))} | D27: {=IF(B27="","",INDEX(_xlfn.SORTBY(INDIRECT("'"&$A$1&"'!$C$10:$C$44"),INDIRECT("'"&$A$1&"'!$B$10:$B$44"),-1),ROWS($B$7:B27)))} | E27: =IF(B27="","",D27/16) | F27: =$C$7-C27 | G27: =IF(B27="","",F27) | I27: Week 7 | J27: {=_xlfn.IFNA(_xlfn.XLOOKUP("Phelpy",INDIRECT("'"&I27&"'!$e$10:$e$44"),INDIRECT("'"&I27&"'!$y$10:$y$44")),"")} | P27: 21 | Q27: =_xlfn.XLOOKUP(P27,Table2[Rank],Table2[Player]) | R27: {=_xlfn.XLOOKUP(Q27,Table2[Player],Season!$T$5:$T$39)} | S27: =IFERROR(SUM(_xlfn.XLOOKUP(Q27,Table2[Player],Table2[Season Wins]))/SUM(Season!$B$3:$S$3),0) | T27: =$R$7-R27 | U27: =_xlfn.XLOOKUP(Q27,Winnings!$A$5:$A$39,Winnings!$U$5:$U$39)
A28: 22 | B28: =IFERROR(INDEX(_xlfn.SORTBY(INDIRECT("'"&$A$1&"'!$E$10:$E$44"),INDIRECT("'"&$A$1&"'!$B$10:$B$44"),-1),ROWS($B$7:B28)),"") | C28: {=IF(B28="","",INDEX(_xlfn.SORTBY(INDIRECT("'"&$A$1&"'!$B$10:$B$44"),INDIRECT("'"&$A$1&"'!$B$10:$B$44"),-1),ROWS($B$7:B28)))} | D28: {=IF(B28="","",INDEX(_xlfn.SORTBY(INDIRECT("'"&$A$1&"'!$C$10:$C$44"),INDIRECT("'"&$A$1&"'!$B$10:$B$44"),-1),ROWS($B$7:B28)))} | E28: =IF(B28="","",D28/16) | F28: =$C$7-C28 | G28: =IF(B28="","",F28) | I28: Week 8 | J28: {=_xlfn.IFNA(_xlfn.XLOOKUP("Phelpy",INDIRECT("'"&I28&"'!$e$10:$e$44"),INDIRECT("'"&I28&"'!$y$10:$y$44")),"")} | P28: 22 | Q28: =_xlfn.XLOOKUP(P28,Table2[Rank],Table2[Player]) | R28: {=_xlfn.XLOOKUP(Q28,Table2[Player],Season!$T$5:$T$39)} | S28: =IFERROR(SUM(_xlfn.XLOOKUP(Q28,Table2[Player],Table2[Season Wins]))/SUM(Season!$B$3:$S$3),0) | T28: =$R$7-R28 | U28: =_xlfn.XLOOKUP(Q28,Winnings!$A$5:$A$39,Winnings!$U$5:$U$39)
A29: 23 | B29: =IFERROR(INDEX(_xlfn.SORTBY(INDIRECT("'"&$A$1&"'!$E$10:$E$44"),INDIRECT("'"&$A$1&"'!$B$10:$B$44"),-1),ROWS($B$7:B29)),"") | C29: {=IF(B29="","",INDEX(_xlfn.SORTBY(INDIRECT("'"&$A$1&"'!$B$10:$B$44"),INDIRECT("'"&$A$1&"'!$B$10:$B$44"),-1),ROWS($B$7:B29)))} | D29: {=IF(B29="","",INDEX(_xlfn.SORTBY(INDIRECT("'"&$A$1&"'!$C$10:$C$44"),INDIRECT("'"&$A$1&"'!$B$10:$B$44"),-1),ROWS($B$7:B29)))} | E29: =IF(B29="","",D29/16) | F29: =$C$7-C29 | G29: =IF(B29="","",F29) | I29: Week 9 | J29: {=_xlfn.IFNA(_xlfn.XLOOKUP("Phelpy",INDIRECT("'"&I29&"'!$e$10:$e$44"),INDIRECT("'"&I29&"'!$y$10:$y$44")),"")} | P29: 23 | Q29: =_xlfn.XLOOKUP(P29,Table2[Rank],Table2[Player]) | R29: {=_xlfn.XLOOKUP(Q29,Table2[Player],Season!$T$5:$T$39)} | S29: =IFERROR(SUM(_xlfn.XLOOKUP(Q29,Table2[Player],Table2[Season Wins]))/SUM(Season!$B$3:$S$3),0) | T29: =$R$7-R29 | U29: =_xlfn.XLOOKUP(Q29,Winnings!$A$5:$A$39,Winnings!$U$5:$U$39)
A30: 24 | B30: =IFERROR(INDEX(_xlfn.SORTBY(INDIRECT("'"&$A$1&"'!$E$10:$E$44"),INDIRECT("'"&$A$1&"'!$B$10:$B$44"),-1),ROWS($B$7:B30)),"") | C30: {=IF(B30="","",INDEX(_xlfn.SORTBY(INDIRECT("'"&$A$1&"'!$B$10:$B$44"),INDIRECT("'"&$A$1&"'!$B$10:$B$44"),-1),ROWS($B$7:B30)))} | D30: {=IF(B30="","",INDEX(_xlfn.SORTBY(INDIRECT("'"&$A$1&"'!$C$10:$C$44"),INDIRECT("'"&$A$1&"'!$B$10:$B$44"),-1),ROWS($B$7:B30)))} | E30: =IF(B30="","",D30/16) | F30: =$C$7-C30 | G30: =IF(B30="","",F30) | I30: Week 10 | J30: {=_xlfn.IFNA(_xlfn.XLOOKUP("Phelpy",INDIRECT("'"&I30&"'!$e$10:$e$44"),INDIRECT("'"&I30&"'!$y$10:$y$44")),"")} | P30: 24 | Q30: =_xlfn.XLOOKUP(P30,Table2[Rank],Table2[Player]) | R30: {=_xlfn.XLOOKUP(Q30,Table2[Player],Season!$T$5:$T$39)} | S30: =IFERROR(SUM(_xlfn.XLOOKUP(Q30,Table2[Player],Table2[Season Wins]))/SUM(Season!$B$3:$S$3),0) | T30: =$R$7-R30 | U30: =_xlfn.XLOOKUP(Q30,Winnings!$A$5:$A$39,Winnings!$U$5:$U$39)
A31: 25 | B31: =IFERROR(INDEX(_xlfn.SORTBY(INDIRECT("'"&$A$1&"'!$E$10:$E$44"),INDIRECT("'"&$A$1&"'!$B$10:$B$44"),-1),ROWS($B$7:B31)),"") | C31: {=IF(B31="","",INDEX(_xlfn.SORTBY(INDIRECT("'"&$A$1&"'!$B$10:$B$44"),INDIRECT("'"&$A$1&"'!$B$10:$B$44"),-1),ROWS($B$7:B31)))} | D31: {=IF(B31="","",INDEX(_xlfn.SORTBY(INDIRECT("'"&$A$1&"'!$C$10:$C$44"),INDIRECT("'"&$A$1&"'!$B$10:$B$44"),-1),ROWS($B$7:B31)))} | E31: =IF(B31="","",D31/16) | F31: =$C$7-C31 | G31: =IF(B31="","",F31) | I31: Week 11 | J31: {=_xlfn.IFNA(_xlfn.XLOOKUP("Phelpy",INDIRECT("'"&I31&"'!$e$10:$e$44"),INDIRECT("'"&I31&"'!$y$10:$y$44")),"")} | P31: 25 | Q31: =_xlfn.XLOOKUP(P31,Table2[Rank],Table2[Player]) | R31: {=_xlfn.XLOOKUP(Q31,Table2[Player],Season!$T$5:$T$39)} | S31: =IFERROR(SUM(_xlfn.XLOOKUP(Q31,Table2[Player],Table2[Season Wins]))/SUM(Season!$B$3:$S$3),0) | T31: =$R$7-R31 | U31: =_xlfn.XLOOKUP(Q31,Winnings!$A$5:$A$39,Winnings!$U$5:$U$39)
A32: 26 | B32: =IFERROR(INDEX(_xlfn.SORTBY(INDIRECT("'"&$A$1&"'!$E$10:$E$44"),INDIRECT("'"&$A$1&"'!$B$10:$B$44"),-1),ROWS($B$7:B32)),"") | C32: {=IF(B32="","",INDEX(_xlfn.SORTBY(INDIRECT("'"&$A$1&"'!$B$10:$B$44"),INDIRECT("'"&$A$1&"'!$B$10:$B$44"),-1),ROWS($B$7:B32)))} | D32: {=IF(B32="","",INDEX(_xlfn.SORTBY(INDIRECT("'"&$A$1&"'!$C$10:$C$44"),INDIRECT("'"&$A$1&"'!$B$10:$B$44"),-1),ROWS($B$7:B32)))} | E32: =IF(B32="","",D32/16) | F32: =$C$7-C32 | G32: =IF(B32="","",F32) | I32: Week 12 | J32: {=_xlfn.IFNA(_xlfn.XLOOKUP("Phelpy",INDIRECT("'"&I32&"'!$e$10:$e$44"),INDIRECT("'"&I32&"'!$y$10:$y$44")),"")} | P32: 26 | Q32: =_xlfn.XLOOKUP(P32,Table2[Rank],Table2[Player]) | R32: {=_xlfn.XLOOKUP(Q32,Table2[Player],Season!$T$5:$T$39)} | S32: =IFERROR(SUM(_xlfn.XLOOKUP(Q32,Table2[Player],Table2[Season Wins]))/SUM(Season!$B$3:$S$3),0) | T32: =$R$7-R32 | U32: =_xlfn.XLOOKUP(Q32,Winnings!$A$5:$A$39,Winnings!$U$5:$U$39)
... A38: 32 | B38: =IFERROR(INDEX(_xlfn.SORTBY(INDIRECT("'"&$A$1&"'!$E$10:$E$44"),INDIRECT("'"&$A$1&"'!$B$10:$B$44"),-1),ROWS($B$7:B38)),"") | C38: {=IF(B38="","",INDEX(_xlfn.SORTBY(INDIRECT("'"&$A$1&"'!$B$10:$B$44"),INDIRECT("'"&$A$1&"'!$B$10:$B$44"),-1),ROWS($B$7:B38)))} | D38: {=IF(B38="","",INDEX(_xlfn.SORTBY(INDIRECT("'"&$A$1&"'!$C$10:$C$44"),INDIRECT("'"&$A$1&"'!$B$10:$B$44"),-1),ROWS($B$7:B38)))} | E38: =IF(B38="","",D38/16) | F38: =$C$7-C38 | G38: =IF(B38="","",F38) | I38: Week 18 | J38: {=_xlfn.IFNA(_xlfn.XLOOKUP("Phelpy",INDIRECT("'"&I38&"'!$e$10:$e$44"),INDIRECT("'"&I38&"'!$y$10:$y$44")),"")} | P38: 32 | Q38: =_xlfn.XLOOKUP(P38,Table2[Rank],Table2[Player]) | R38: {=_xlfn.XLOOKUP(Q38,Table2[Player],Season!$T$5:$T$39)} | S38: =IFERROR(SUM(_xlfn.XLOOKUP(Q38,Table2[Player],Table2[Season Wins]))/SUM(Season!$B$3:$S$3),0) | T38: =$R$7-R38 | U38: =_xlfn.XLOOKUP(Q38,Winnings!$A$5:$A$39,Winnings!$U$5:$U$39)
A39: 33 | B39: =IFERROR(INDEX(_xlfn.SORTBY(INDIRECT("'"&$A$1&"'!$E$10:$E$44"),INDIRECT("'"&$A$1&"'!$B$10:$B$44"),-1),ROWS($B$7:B39)),"") | C39: {=IF(B39="","",INDEX(_xlfn.SORTBY(INDIRECT("'"&$A$1&"'!$B$10:$B$44"),INDIRECT("'"&$A$1&"'!$B$10:$B$44"),-1),ROWS($B$7:B39)))} | D39: {=IF(B39="","",INDEX(_xlfn.SORTBY(INDIRECT("'"&$A$1&"'!$C$10:$C$44"),INDIRECT("'"&$A$1&"'!$B$10:$B$44"),-1),ROWS($B$7:B39)))} | E39: =IF(B39="","",D39/16) | F39: =$C$7-C39 | G39: =IF(B39="","",F39) | P39: 33 | Q39: =_xlfn.XLOOKUP(P39,Table2[Rank],Table2[Player]) | R39: {=_xlfn.XLOOKUP(Q39,Table2[Player],Season!$T$5:$T$39)} | S39: =IFERROR(SUM(_xlfn.XLOOKUP(Q39,Table2[Player],Table2[Season Wins]))/SUM(Season!$B$3:$S$3),0) | T39: =$R$7-R39 | U39: =_xlfn.XLOOKUP(Q39,Winnings!$A$5:$A$39,Winnings!$U$5:$U$39)
A40: 34 | B40: =IFERROR(INDEX(_xlfn.SORTBY(INDIRECT("'"&$A$1&"'!$E$10:$E$44"),INDIRECT("'"&$A$1&"'!$B$10:$B$44"),-1),ROWS($B$7:B40)),"") | C40: {=IF(B40="","",INDEX(_xlfn.SORTBY(INDIRECT("'"&$A$1&"'!$B$10:$B$44"),INDIRECT("'"&$A$1&"'!$B$10:$B$44"),-1),ROWS($B$7:B40)))} | D40: {=IF(B40="","",INDEX(_xlfn.SORTBY(INDIRECT("'"&$A$1&"'!$C$10:$C$44"),INDIRECT("'"&$A$1&"'!$B$10:$B$44"),-1),ROWS($B$7:B40)))} | E40: =IF(B40="","",D40/16) | F40: =$C$7-C40 | G40: =IF(B40="","",F40) | P40: 34 | Q40: =_xlfn.XLOOKUP(P40,Table2[Rank],Table2[Player]) | R40: {=_xlfn.XLOOKUP(Q40,Table2[Player],Season!$T$5:$T$39)} | S40: =IFERROR(SUM(_xlfn.XLOOKUP(Q40,Table2[Player],Table2[Season Wins]))/SUM(Season!$B$3:$S$3),0) | T40: =$R$7-R40 | U40: =_xlfn.XLOOKUP(Q40,Winnings!$A$5:$A$39,Winnings!$U$5:$U$39)
A41: 35 | B41: =IFERROR(INDEX(_xlfn.SORTBY(INDIRECT("'"&$A$1&"'!$E$10:$E$44"),INDIRECT("'"&$A$1&"'!$B$10:$B$44"),-1),ROWS($B$7:B41)),"") | C41: {=IF(B41="","",INDEX(_xlfn.SORTBY(INDIRECT("'"&$A$1&"'!$B$10:$B$44"),INDIRECT("'"&$A$1&"'!$B$10:$B$44"),-1),ROWS($B$7:B41)))} | D41: {=IF(B41="","",INDEX(_xlfn.SORTBY(INDIRECT("'"&$A$1&"'!$C$10:$C$44"),INDIRECT("'"&$A$1&"'!$B$10:$B$44"),-1),ROWS($B$7:B41)))} | E41: =IF(B41="","",D41/16) | F41: =$C$7-C41 | G41: =IF(B41="","",F41) | P41: 35 | Q41: =_xlfn.XLOOKUP(P41,Table2[Rank],Table2[Player]) | R41: {=_xlfn.XLOOKUP(Q41,Table2[Player],Season!$T$5:$T$39)} | S41: =IFERROR(SUM(_xlfn.XLOOKUP(Q41,Table2[Player],Table2[Season Wins]))/SUM(Season!$B$3:$S$3),0) | T41: =$R$7-R41 | U41: =_xlfn.XLOOKUP(Q41,Winnings!$A$5:$A$39,Winnings!$U$5:$U$39)

Sheet Season
A1: 📈 SEASON TRACKER
A3: # of games | B3: 16 | C3: 16 | D3: 16 | E3: 16 | F3: 15 | G3: 14 | H3: 14 | I3: 14 | J3: 15 | K3: 14 | L3: 13 | M3: 16 | N3: 14 | O3: 15 | P3: 16 | Q3: 16 | R3: 16 | S3: 16
A4: Player | B4: Week 1 | C4: Week 2 | D4: Week 3 | E4: Week 4 | F4: Week 5 | G4: Week 6 | H4: Week 7 | I4: Week 8 | J4: Week 9 | K4: Week 10 | L4: Week 11 | M4: Week 12 | N4: Week 13 | O4: Week 14 | P4: Week 15 | Q4: Week 16 | R4: Week 17 | S4: Week 18 | T4: Season Wins | U4: Avg Wins | V4: Best | W4: Worst | X4: Rank | Y4: Season Win %
A5: Bob h | B5: {=_xlfn.IFNA(_xlfn.XLOOKUP($A5,INDIRECT("'"&B$4&"'!$E$10:$E$44"),INDIRECT("'"&B$4&"'!$b$10:$b$44"))," ")} | C5: {=_xlfn.IFNA(_xlfn.XLOOKUP($A5,INDIRECT("'"&C$4&"'!$E$10:$E$44"),INDIRECT("'"&C$4&"'!$b$10:$b$44"))," ")} | D5: {=_xlfn.IFNA(_xlfn.XLOOKUP($A5,INDIRECT("'"&D$4&"'!$E$10:$E$44"),INDIRECT("'"&D$4&"'!$b$10:$b$44"))," ")} | E5: {=_xlfn.IFNA(_xlfn.XLOOKUP($A5,INDIRECT("'"&E$4&"'!$E$10:$E$44"),INDIRECT("'"&E$4&"'!$b$10:$b$44"))," ")} | F5: {=_xlfn.IFNA(_xlfn.XLOOKUP($A5,INDIRECT("'"&F$4&"'!$E$10:$E$44"),INDIRECT("'"&F$4&"'!$b$10:$b$44"))," ")} | G5: {=_xlfn.IFNA(_xlfn.XLOOKUP($A5,INDIRECT("'"&G$4&"'!$E$10:$E$44"),INDIRECT("'"&G$4&"'!$b$10:$b$44"))," ")} | H5: {=_xlfn.IFNA(_xlfn.XLOOKUP($A5,INDIRECT("'"&H$4&"'!$E$10:$E$44"),INDIRECT("'"&H$4&"'!$b$10:$b$44"))," ")} | I5: {=_xlfn.IFNA(_xlfn.XLOOKUP($A5,INDIRECT("'"&I$4&"'!$E$10:$E$44"),INDIRECT("'"&I$4&"'!$b$10:$b$44"))," ")} | ... Q5: {=_xlfn.IFNA(_xlfn.XLOOKUP($A5,INDIRECT("'"&Q$4&"'!$E$10:$E$44"),INDIRECT("'"&Q$4&"'!$b$10:$b$44"))," ")} | T5: =SUM(B5:K5) | U5: =IFERROR(AVERAGEIF(B5:Q5,">=0"),0) | V5: =IFERROR(MAX(B5:Q5),0) | W5: =IFERROR(_xlfn.MINIFS(B5:Q5,B5:Q5,">0"),0) | X5: =RANK(T5,$T$5:$T$39)+COUNTIF($T$5:T5,T5)-1 | Y5: {=IFERROR(T5/SUMPRODUCT(($B5:$C5<>"")*$B$3:$C$3),0)}
A6: Brick_Hauss | B6: {=_xlfn.IFNA(_xlfn.XLOOKUP($A6,INDIRECT("'"&B$4&"'!$E$10:$E$44"),INDIRECT("'"&B$4&"'!$b$10:$b$44"))," ")} | C6: {=_xlfn.IFNA(_xlfn.XLOOKUP($A6,INDIRECT("'"&C$4&"'!$E$10:$E$44"),INDIRECT("'"&C$4&"'!$b$10:$b$44"))," ")} | D6: {=_xlfn.IFNA(_xlfn.XLOOKUP($A6,INDIRECT("'"&D$4&"'!$E$10:$E$44"),INDIRECT("'"&D$4&"'!$b$10:$b$44"))," ")} | E6: {=_xlfn.IFNA(_xlfn.XLOOKUP($A6,INDIRECT("'"&E$4&"'!$E$10:$E$44"),INDIRECT("'"&E$4&"'!$b$10:$b$44"))," ")} | F6: {=_xlfn.IFNA(_xlfn.XLOOKUP($A6,INDIRECT("'"&F$4&"'!$E$10:$E$44"),INDIRECT("'"&F$4&"'!$b$10:$b$44"))," ")} | G6: {=_xlfn.IFNA(_xlfn.XLOOKUP($A6,INDIRECT("'"&G$4&"'!$E$10:$E$44"),INDIRECT("'"&G$4&"'!$b$10:$b$44"))," ")} | H6: {=_xlfn.IFNA(_xlfn.XLOOKUP($A6,INDIRECT("'"&H$4&"'!$E$10:$E$44"),INDIRECT("'"&H$4&"'!$b$10:$b$44"))," ")} | I6: {=_xlfn.IFNA(_xlfn.XLOOKUP($A6,INDIRECT("'"&I$4&"'!$E$10:$E$44"),INDIRECT("'"&I$4&"'!$b$10:$b$44"))," ")} | ... Q6: {=_xlfn.IFNA(_xlfn.XLOOKUP($A6,INDIRECT("'"&Q$4&"'!$E$10:$E$44"),INDIRECT("'"&Q$4&"'!$b$10:$b$44"))," ")} | T6: =SUM(B6:K6) | U6: =IFERROR(AVERAGEIF(B6:Q6,">=0"),0) | V6: =IFERROR(MAX(B6:Q6),0) | W6: =IFERROR(_xlfn.MINIFS(B6:Q6,B6:Q6,">0"),0) | X6: =RANK(T6,$T$5:$T$39)+COUNTIF($T$5:T6,T6)-1 | Y6: {=IFERROR(T6/SUMPRODUCT(($B6:$C6<>"")*$B$3:$C$3),0)}
A7: CraneGuy936 | B7: {=_xlfn.IFNA(_xlfn.XLOOKUP($A7,INDIRECT("'"&B$4&"'!$E$10:$E$44"),INDIRECT("'"&B$4&"'!$b$10:$b$44"))," ")} | C7: {=_xlfn.IFNA(_xlfn.XLOOKUP($A7,INDIRECT("'"&C$4&"'!$E$10:$E$44"),INDIRECT("'"&C$4&"'!$b$10:$b$44"))," ")} | D7: {=_xlfn.IFNA(_xlfn.XLOOKUP($A7,INDIRECT("'"&D$4&"'!$E$10:$E$44"),INDIRECT("'"&D$4&"'!$b$10:$b$44"))," ")} | E7: {=_xlfn.IFNA(_xlfn.XLOOKUP($A7,INDIRECT("'"&E$4&"'!$E$10:$E$44"),INDIRECT("'"&E$4&"'!$b$10:$b$44"))," ")} | F7: {=_xlfn.IFNA(_xlfn.XLOOKUP($A7,INDIRECT("'"&F$4&"'!$E$10:$E$44"),INDIRECT("'"&F$4&"'!$b$10:$b$44"))," ")} | G7: {=_xlfn.IFNA(_xlfn.XLOOKUP($A7,INDIRECT("'"&G$4&"'!$E$10:$E$44"),INDIRECT("'"&G$4&"'!$b$10:$b$44"))," ")} | H7: {=_xlfn.IFNA(_xlfn.XLOOKUP($A7,INDIRECT("'"&H$4&"'!$E$10:$E$44"),INDIRECT("'"&H$4&"'!$b$10:$b$44"))," ")} | I7: {=_xlfn.IFNA(_xlfn.XLOOKUP($A7,INDIRECT("'"&I$4&"'!$E$10:$E$44"),INDIRECT("'"&I$4&"'!$b$10:$b$44"))," ")} | ... Q7: {=_xlfn.IFNA(_xlfn.XLOOKUP($A7,INDIRECT("'"&Q$4&"'!$E$10:$E$44"),INDIRECT("'"&Q$4&"'!$b$10:$b$44"))," ")} | T7: =SUM(B7:K7) | U7: =IFERROR(AVERAGEIF(B7:Q7,">=0"),0) | V7: =IFERROR(MAX(B7:Q7),0) | W7: =IFERROR(_xlfn.MINIFS(B7:Q7,B7:Q7,">0"),0) | X7: =RANK(T7,$T$5:$T$39)+COUNTIF($T$5:T7,T7)-1 | Y7: {=IFERROR(T7/SUMPRODUCT(($B7:$C7<>"")*$B$3:$C$3),0)}
A8: cuetop | B8: {=_xlfn.IFNA(_xlfn.XLOOKUP($A8,INDIRECT("'"&B$4&"'!$E$10:$E$44"),INDIRECT("'"&B$4&"'!$b$10:$b$44"))," ")} | C8: {=_xlfn.IFNA(_xlfn.XLOOKUP($A8,INDIRECT("'"&C$4&"'!$E$10:$E$44"),INDIRECT("'"&C$4&"'!$b$10:$b$44"))," ")} | D8: {=_xlfn.IFNA(_xlfn.XLOOKUP($A8,INDIRECT("'"&D$4&"'!$E$10:$E$44"),INDIRECT("'"&D$4&"'!$b$10:$b$44"))," ")} | E8: {=_xlfn.IFNA(_xlfn.XLOOKUP($A8,INDIRECT("'"&E$4&"'!$E$10:$E$44"),INDIRECT("'"&E$4&"'!$b$10:$b$44"))," ")} | F8: {=_xlfn.IFNA(_xlfn.XLOOKUP($A8,INDIRECT("'"&F$4&"'!$E$10:$E$44"),INDIRECT("'"&F$4&"'!$b$10:$b$44"))," ")} | G8: {=_xlfn.IFNA(_xlfn.XLOOKUP($A8,INDIRECT("'"&G$4&"'!$E$10:$E$44"),INDIRECT("'"&G$4&"'!$b$10:$b$44"))," ")} | H8: {=_xlfn.IFNA(_xlfn.XLOOKUP($A8,INDIRECT("'"&H$4&"'!$E$10:$E$44"),INDIRECT("'"&H$4&"'!$b$10:$b$44"))," ")} | I8: {=_xlfn.IFNA(_xlfn.XLOOKUP($A8,INDIRECT("'"&I$4&"'!$E$10:$E$44"),INDIRECT("'"&I$4&"'!$b$10:$b$44"))," ")} | ... Q8: {=_xlfn.IFNA(_xlfn.XLOOKUP($A8,INDIRECT("'"&Q$4&"'!$E$10:$E$44"),INDIRECT("'"&Q$4&"'!$b$10:$b$44"))," ")} | T8: =SUM(B8:K8) | U8: =IFERROR(AVERAGEIF(B8:Q8,">=0"),0) | V8: =IFERROR(MAX(B8:Q8),0) | W8: =IFERROR(_xlfn.MINIFS(B8:Q8,B8:Q8,">0"),0) | X8: =RANK(T8,$T$5:$T$39)+COUNTIF($T$5:T8,T8)-1 | Y8: {=IFERROR(T8/SUMPRODUCT(($B8:$C8<>"")*$B$3:$C$3),0)}
A9: Ddupuy | B9: {=_xlfn.IFNA(_xlfn.XLOOKUP($A9,INDIRECT("'"&B$4&"'!$E$10:$E$44"),INDIRECT("'"&B$4&"'!$b$10:$b$44"))," ")} | C9: {=_xlfn.IFNA(_xlfn.XLOOKUP($A9,INDIRECT("'"&C$4&"'!$E$10:$E$44"),INDIRECT("'"&C$4&"'!$b$10:$b$44"))," ")} | D9: {=_xlfn.IFNA(_xlfn.XLOOKUP($A9,INDIRECT("'"&D$4&"'!$E$10:$E$44"),INDIRECT("'"&D$4&"'!$b$10:$b$44"))," ")} | E9: {=_xlfn.IFNA(_xlfn.XLOOKUP($A9,INDIRECT("'"&E$4&"'!$E$10:$E$44"),INDIRECT("'"&E$4&"'!$b$10:$b$44"))," ")} | F9: {=_xlfn.IFNA(_xlfn.XLOOKUP($A9,INDIRECT("'"&F$4&"'!$E$10:$E$44"),INDIRECT("'"&F$4&"'!$b$10:$b$44"))," ")} | G9: {=_xlfn.IFNA(_xlfn.XLOOKUP($A9,INDIRECT("'"&G$4&"'!$E$10:$E$44"),INDIRECT("'"&G$4&"'!$b$10:$b$44"))," ")} | H9: {=_xlfn.IFNA(_xlfn.XLOOKUP($A9,INDIRECT("'"&H$4&"'!$E$10:$E$44"),INDIRECT("'"&H$4&"'!$b$10:$b$44"))," ")} | I9: {=_xlfn.IFNA(_xlfn.XLOOKUP($A9,INDIRECT("'"&I$4&"'!$E$10:$E$44"),INDIRECT("'"&I$4&"'!$b$10:$b$44"))," ")} | ... Q9: {=_xlfn.IFNA(_xlfn.XLOOKUP($A9,INDIRECT("'"&Q$4&"'!$E$10:$E$44"),INDIRECT("'"&Q$4&"'!$b$10:$b$44"))," ")} | T9: =SUM(B9:K9) | U9: =IFERROR(AVERAGEIF(B9:Q9,">=0"),0) | V9: =IFERROR(MAX(B9:Q9),0) | W9: =IFERROR(_xlfn.MINIFS(B9:Q9,B9:Q9,">0"),0) | X9: =RANK(T9,$T$5:$T$39)+COUNTIF($T$5:T9,T9)-1 | Y9: {=IFERROR(T9/SUMPRODUCT(($B9:$C9<>"")*$B$3:$C$3),0)}
A10: Debe | B10: {=_xlfn.IFNA(_xlfn.XLOOKUP($A10,INDIRECT("'"&B$4&"'!$E$10:$E$44"),INDIRECT("'"&B$4&"'!$b$10:$b$44"))," ")} | C10: {=_xlfn.IFNA(_xlfn.XLOOKUP($A10,INDIRECT("'"&C$4&"'!$E$10:$E$44"),INDIRECT("'"&C$4&"'!$b$10:$b$44"))," ")} | D10: {=_xlfn.IFNA(_xlfn.XLOOKUP($A10,INDIRECT("'"&D$4&"'!$E$10:$E$44"),INDIRECT("'"&D$4&"'!$b$10:$b$44"))," ")} | E10: {=_xlfn.IFNA(_xlfn.XLOOKUP($A10,INDIRECT("'"&E$4&"'!$E$10:$E$44"),INDIRECT("'"&E$4&"'!$b$10:$b$44"))," ")} | F10: {=_xlfn.IFNA(_xlfn.XLOOKUP($A10,INDIRECT("'"&F$4&"'!$E$10:$E$44"),INDIRECT("'"&F$4&"'!$b$10:$b$44"))," ")} | G10: {=_xlfn.IFNA(_xlfn.XLOOKUP($A10,INDIRECT("'"&G$4&"'!$E$10:$E$44"),INDIRECT("'"&G$4&"'!$b$10:$b$44"))," ")} | H10: {=_xlfn.IFNA(_xlfn.XLOOKUP($A10,INDIRECT("'"&H$4&"'!$E$10:$E$44"),INDIRECT("'"&H$4&"'!$b$10:$b$44"))," ")} | I10: {=_xlfn.IFNA(_xlfn.XLOOKUP($A10,INDIRECT("'"&I$4&"'!$E$10:$E$44"),INDIRECT("'"&I$4&"'!$b$10:$b$44"))," ")} | ... Q10: {=_xlfn.IFNA(_xlfn.XLOOKUP($A10,INDIRECT("'"&Q$4&"'!$E$10:$E$44"),INDIRECT("'"&Q$4&"'!$b$10:$b$44"))," ")} | T10: =SUM(B10:K10) | U10: =IFERROR(AVERAGEIF(B10:Q10,">=0"),0) | V10: =IFERROR(MAX(B10:Q10),0) | W10: =IFERROR(_xlfn.MINIFS(B10:Q10,B10:Q10,">0"),0) | X10: =RANK(T10,$T$5:$T$39)+COUNTIF($T$5:T10,T10)-1 | Y10: {=IFERROR(T10/SUMPRODUCT(($B10:$C10<>"")*$B$3:$C$3),0)}
A11: DPSOG | B11: {=_xlfn.IFNA(_xlfn.XLOOKUP($A11,INDIRECT("'"&B$4&"'!$E$10:$E$44"),INDIRECT("'"&B$4&"'!$b$10:$b$44"))," ")} | C11: {=_xlfn.IFNA(_xlfn.XLOOKUP($A11,INDIRECT("'"&C$4&"'!$E$10:$E$44"),INDIRECT("'"&C$4&"'!$b$10:$b$44"))," ")} | D11: {=_xlfn.IFNA(_xlfn.XLOOKUP($A11,INDIRECT("'"&D$4&"'!$E$10:$E$44"),INDIRECT("'"&D$4&"'!$b$10:$b$44"))," ")} | E11: {=_xlfn.IFNA(_xlfn.XLOOKUP($A11,INDIRECT("'"&E$4&"'!$E$10:$E$44"),INDIRECT("'"&E$4&"'!$b$10:$b$44"))," ")} | F11: {=_xlfn.IFNA(_xlfn.XLOOKUP($A11,INDIRECT("'"&F$4&"'!$E$10:$E$44"),INDIRECT("'"&F$4&"'!$b$10:$b$44"))," ")} | G11: {=_xlfn.IFNA(_xlfn.XLOOKUP($A11,INDIRECT("'"&G$4&"'!$E$10:$E$44"),INDIRECT("'"&G$4&"'!$b$10:$b$44"))," ")} | H11: {=_xlfn.IFNA(_xlfn.XLOOKUP($A11,INDIRECT("'"&H$4&"'!$E$10:$E$44"),INDIRECT("'"&H$4&"'!$b$10:$b$44"))," ")} | I11: {=_xlfn.IFNA(_xlfn.XLOOKUP($A11,INDIRECT("'"&I$4&"'!$E$10:$E$44"),INDIRECT("'"&I$4&"'!$b$10:$b$44"))," ")} | ... Q11: {=_xlfn.IFNA(_xlfn.XLOOKUP($A11,INDIRECT("'"&Q$4&"'!$E$10:$E$44"),INDIRECT("'"&Q$4&"'!$b$10:$b$44"))," ")} | T11: =SUM(B11:K11) | U11: =IFERROR(AVERAGEIF(B11:Q11,">=0"),0) | V11: =IFERROR(MAX(B11:Q11),0) | W11: =IFERROR(_xlfn.MINIFS(B11:Q11,B11:Q11,">0"),0) | X11: =RANK(T11,$T$5:$T$39)+COUNTIF($T$5:T11,T11)-1 | Y11: {=IFERROR(T11/SUMPRODUCT(($B11:$C11<>"")*$B$3:$C$3),0)}
A12: FMF Doc | B12: {=_xlfn.IFNA(_xlfn.XLOOKUP($A12,INDIRECT("'"&B$4&"'!$E$10:$E$44"),INDIRECT("'"&B$4&"'!$b$10:$b$44"))," ")} | C12: {=_xlfn.IFNA(_xlfn.XLOOKUP($A12,INDIRECT("'"&C$4&"'!$E$10:$E$44"),INDIRECT("'"&C$4&"'!$b$10:$b$44"))," ")} | D12: {=_xlfn.IFNA(_xlfn.XLOOKUP($A12,INDIRECT("'"&D$4&"'!$E$10:$E$44"),INDIRECT("'"&D$4&"'!$b$10:$b$44"))," ")} | E12: {=_xlfn.IFNA(_xlfn.XLOOKUP($A12,INDIRECT("'"&E$4&"'!$E$10:$E$44"),INDIRECT("'"&E$4&"'!$b$10:$b$44"))," ")} | F12: {=_xlfn.IFNA(_xlfn.XLOOKUP($A12,INDIRECT("'"&F$4&"'!$E$10:$E$44"),INDIRECT("'"&F$4&"'!$b$10:$b$44"))," ")} | G12: {=_xlfn.IFNA(_xlfn.XLOOKUP($A12,INDIRECT("'"&G$4&"'!$E$10:$E$44"),INDIRECT("'"&G$4&"'!$b$10:$b$44"))," ")} | H12: {=_xlfn.IFNA(_xlfn.XLOOKUP($A12,INDIRECT("'"&H$4&"'!$E$10:$E$44"),INDIRECT("'"&H$4&"'!$b$10:$b$44"))," ")} | I12: {=_xlfn.IFNA(_xlfn.XLOOKUP($A12,INDIRECT("'"&I$4&"'!$E$10:$E$44"),INDIRECT("'"&I$4&"'!$b$10:$b$44"))," ")} | ... Q12: {=_xlfn.IFNA(_xlfn.XLOOKUP($A12,INDIRECT("'"&Q$4&"'!$E$10:$E$44"),INDIRECT("'"&Q$4&"'!$b$10:$b$44"))," ")} | T12: =SUM(B12:K12) | U12: =IFERROR(AVERAGEIF(B12:Q12,">=0"),0) | V12: =IFERROR(MAX(B12:Q12),0) | W12: =IFERROR(_xlfn.MINIFS(B12:Q12,B12:Q12,">0"),0) | X12: =RANK(T12,$T$5:$T$39)+COUNTIF($T$5:T12,T12)-1 | Y12: {=IFERROR(T12/SUMPRODUCT(($B12:$C12<>"")*$B$3:$C$3),0)}
A13: Frankethetank | B13: {=_xlfn.IFNA(_xlfn.XLOOKUP($A13,INDIRECT("'"&B$4&"'!$E$10:$E$44"),INDIRECT("'"&B$4&"'!$b$10:$b$44"))," ")} | C13: {=_xlfn.IFNA(_xlfn.XLOOKUP($A13,INDIRECT("'"&C$4&"'!$E$10:$E$44"),INDIRECT("'"&C$4&"'!$b$10:$b$44"))," ")} | D13: {=_xlfn.IFNA(_xlfn.XLOOKUP($A13,INDIRECT("'"&D$4&"'!$E$10:$E$44"),INDIRECT("'"&D$4&"'!$b$10:$b$44"))," ")} | E13: {=_xlfn.IFNA(_xlfn.XLOOKUP($A13,INDIRECT("'"&E$4&"'!$E$10:$E$44"),INDIRECT("'"&E$4&"'!$b$10:$b$44"))," ")} | F13: {=_xlfn.IFNA(_xlfn.XLOOKUP($A13,INDIRECT("'"&F$4&"'!$E$10:$E$44"),INDIRECT("'"&F$4&"'!$b$10:$b$44"))," ")} | G13: {=_xlfn.IFNA(_xlfn.XLOOKUP($A13,INDIRECT("'"&G$4&"'!$E$10:$E$44"),INDIRECT("'"&G$4&"'!$b$10:$b$44"))," ")} | H13: {=_xlfn.IFNA(_xlfn.XLOOKUP($A13,INDIRECT("'"&H$4&"'!$E$10:$E$44"),INDIRECT("'"&H$4&"'!$b$10:$b$44"))," ")} | I13: {=_xlfn.IFNA(_xlfn.XLOOKUP($A13,INDIRECT("'"&I$4&"'!$E$10:$E$44"),INDIRECT("'"&I$4&"'!$b$10:$b$44"))," ")} | ... Q13: {=_xlfn.IFNA(_xlfn.XLOOKUP($A13,INDIRECT("'"&Q$4&"'!$E$10:$E$44"),INDIRECT("'"&Q$4&"'!$b$10:$b$44"))," ")} | T13: =SUM(B13:K13) | U13: =IFERROR(AVERAGEIF(B13:Q13,">=0"),0) | V13: =IFERROR(MAX(B13:Q13),0) | W13: =IFERROR(_xlfn.MINIFS(B13:Q13,B13:Q13,">0"),0) | X13: =RANK(T13,$T$5:$T$39)+COUNTIF($T$5:T13,T13)-1 | Y13: {=IFERROR(T13/SUMPRODUCT(($B13:$C13<>"")*$B$3:$C$3),0)}
A14: Gr8granpa | B14: {=_xlfn.IFNA(_xlfn.XLOOKUP($A14,INDIRECT("'"&B$4&"'!$E$10:$E$44"),INDIRECT("'"&B$4&"'!$b$10:$b$44"))," ")} | C14: {=_xlfn.IFNA(_xlfn.XLOOKUP($A14,INDIRECT("'"&C$4&"'!$E$10:$E$44"),INDIRECT("'"&C$4&"'!$b$10:$b$44"))," ")} | D14: {=_xlfn.IFNA(_xlfn.XLOOKUP($A14,INDIRECT("'"&D$4&"'!$E$10:$E$44"),INDIRECT("'"&D$4&"'!$b$10:$b$44"))," ")} | E14: {=_xlfn.IFNA(_xlfn.XLOOKUP($A14,INDIRECT("'"&E$4&"'!$E$10:$E$44"),INDIRECT("'"&E$4&"'!$b$10:$b$44"))," ")} | F14: {=_xlfn.IFNA(_xlfn.XLOOKUP($A14,INDIRECT("'"&F$4&"'!$E$10:$E$44"),INDIRECT("'"&F$4&"'!$b$10:$b$44"))," ")} | G14: {=_xlfn.IFNA(_xlfn.XLOOKUP($A14,INDIRECT("'"&G$4&"'!$E$10:$E$44"),INDIRECT("'"&G$4&"'!$b$10:$b$44"))," ")} | H14: {=_xlfn.IFNA(_xlfn.XLOOKUP($A14,INDIRECT("'"&H$4&"'!$E$10:$E$44"),INDIRECT("'"&H$4&"'!$b$10:$b$44"))," ")} | I14: {=_xlfn.IFNA(_xlfn.XLOOKUP($A14,INDIRECT("'"&I$4&"'!$E$10:$E$44"),INDIRECT("'"&I$4&"'!$b$10:$b$44"))," ")} | ... Q14: {=_xlfn.IFNA(_xlfn.XLOOKUP($A14,INDIRECT("'"&Q$4&"'!$E$10:$E$44"),INDIRECT("'"&Q$4&"'!$b$10:$b$44"))," ")} | T14: =SUM(B14:K14) | U14: =IFERROR(AVERAGEIF(B14:Q14,">=0"),0) | V14: =IFERROR(MAX(B14:Q14),0) | W14: =IFERROR(_xlfn.MINIFS(B14:Q14,B14:Q14,">0"),0) | X14: =RANK(T14,$T$5:$T$39)+COUNTIF($T$5:T14,T14)-1 | Y14: {=IFERROR(T14/SUMPRODUCT(($B14:$C14<>"")*$B$3:$C$3),0)}
A15: Ian | B15: {=_xlfn.IFNA(_xlfn.XLOOKUP($A15,INDIRECT("'"&B$4&"'!$E$10:$E$44"),INDIRECT("'"&B$4&"'!$b$10:$b$44"))," ")} | C15: {=_xlfn.IFNA(_xlfn.XLOOKUP($A15,INDIRECT("'"&C$4&"'!$E$10:$E$44"),INDIRECT("'"&C$4&"'!$b$10:$b$44"))," ")} | D15: {=_xlfn.IFNA(_xlfn.XLOOKUP($A15,INDIRECT("'"&D$4&"'!$E$10:$E$44"),INDIRECT("'"&D$4&"'!$b$10:$b$44"))," ")} | E15: {=_xlfn.IFNA(_xlfn.XLOOKUP($A15,INDIRECT("'"&E$4&"'!$E$10:$E$44"),INDIRECT("'"&E$4&"'!$b$10:$b$44"))," ")} | F15: {=_xlfn.IFNA(_xlfn.XLOOKUP($A15,INDIRECT("'"&F$4&"'!$E$10:$E$44"),INDIRECT("'"&F$4&"'!$b$10:$b$44"))," ")} | G15: {=_xlfn.IFNA(_xlfn.XLOOKUP($A15,INDIRECT("'"&G$4&"'!$E$10:$E$44"),INDIRECT("'"&G$4&"'!$b$10:$b$44"))," ")} | H15: {=_xlfn.IFNA(_xlfn.XLOOKUP($A15,INDIRECT("'"&H$4&"'!$E$10:$E$44"),INDIRECT("'"&H$4&"'!$b$10:$b$44"))," ")} | I15: {=_xlfn.IFNA(_xlfn.XLOOKUP($A15,INDIRECT("'"&I$4&"'!$E$10:$E$44"),INDIRECT("'"&I$4&"'!$b$10:$b$44"))," ")} | ... Q15: {=_xlfn.IFNA(_xlfn.XLOOKUP($A15,INDIRECT("'"&Q$4&"'!$E$10:$E$44"),INDIRECT("'"&Q$4&"'!$b$10:$b$44"))," ")} | T15: =SUM(B15:K15) | U15: =IFERROR(AVERAGEIF(B15:Q15,">=0"),0) | V15: =IFERROR(MAX(B15:Q15),0) | W15: =IFERROR(_xlfn.MINIFS(B15:Q15,B15:Q15,">0"),0) | X15: =RANK(T15,$T$5:$T$39)+COUNTIF($T$5:T15,T15)-1 | Y15: {=IFERROR(T15/SUMPRODUCT(($B15:$C15<>"")*$B$3:$C$3),0)}
A16: Jim T | B16: {=_xlfn.IFNA(_xlfn.XLOOKUP($A16,INDIRECT("'"&B$4&"'!$E$10:$E$44"),INDIRECT("'"&B$4&"'!$b$10:$b$44"))," ")} | C16: {=_xlfn.IFNA(_xlfn.XLOOKUP($A16,INDIRECT("'"&C$4&"'!$E$10:$E$44"),INDIRECT("'"&C$4&"'!$b$10:$b$44"))," ")} | D16: {=_xlfn.IFNA(_xlfn.XLOOKUP($A16,INDIRECT("'"&D$4&"'!$E$10:$E$44"),INDIRECT("'"&D$4&"'!$b$10:$b$44"))," ")} | E16: {=_xlfn.IFNA(_xlfn.XLOOKUP($A16,INDIRECT("'"&E$4&"'!$E$10:$E$44"),INDIRECT("'"&E$4&"'!$b$10:$b$44"))," ")} | F16: {=_xlfn.IFNA(_xlfn.XLOOKUP($A16,INDIRECT("'"&F$4&"'!$E$10:$E$44"),INDIRECT("'"&F$4&"'!$b$10:$b$44"))," ")} | G16: {=_xlfn.IFNA(_xlfn.XLOOKUP($A16,INDIRECT("'"&G$4&"'!$E$10:$E$44"),INDIRECT("'"&G$4&"'!$b$10:$b$44"))," ")} | H16: {=_xlfn.IFNA(_xlfn.XLOOKUP($A16,INDIRECT("'"&H$4&"'!$E$10:$E$44"),INDIRECT("'"&H$4&"'!$b$10:$b$44"))," ")} | I16: {=_xlfn.IFNA(_xlfn.XLOOKUP($A16,INDIRECT("'"&I$4&"'!$E$10:$E$44"),INDIRECT("'"&I$4&"'!$b$10:$b$44"))," ")} | ... Q16: {=_xlfn.IFNA(_xlfn.XLOOKUP($A16,INDIRECT("'"&Q$4&"'!$E$10:$E$44"),INDIRECT("'"&Q$4&"'!$b$10:$b$44"))," ")} | T16: =SUM(B16:K16) | U16: =IFERROR(AVERAGEIF(B16:Q16,">=0"),0) | V16: =IFERROR(MAX(B16:Q16),0) | W16: =IFERROR(_xlfn.MINIFS(B16:Q16,B16:Q16,">0"),0) | X16: =RANK(T16,$T$5:$T$39)+COUNTIF($T$5:T16,T16)-1 | Y16: {=IFERROR(T16/SUMPRODUCT(($B16:$C16<>"")*$B$3:$C$3),0)}
... A39: Zach N | B39: {=_xlfn.IFNA(_xlfn.XLOOKUP($A39,INDIRECT("'"&B$4&"'!$E$10:$E$44"),INDIRECT("'"&B$4&"'!$b$10:$b$44"))," ")} | C39: {=_xlfn.IFNA(_xlfn.XLOOKUP($A39,INDIRECT("'"&C$4&"'!$E$10:$E$44"),INDIRECT("'"&C$4&"'!$b$10:$b$44"))," ")} | D39: {=_xlfn.IFNA(_xlfn.XLOOKUP($A39,INDIRECT("'"&D$4&"'!$E$10:$E$44"),INDIRECT("'"&D$4&"'!$b$10:$b$44"))," ")} | E39: {=_xlfn.IFNA(_xlfn.XLOOKUP($A39,INDIRECT("'"&E$4&"'!$E$10:$E$44"),INDIRECT("'"&E$4&"'!$b$10:$b$44"))," ")} | F39: {=_xlfn.IFNA(_xlfn.XLOOKUP($A39,INDIRECT("'"&F$4&"'!$E$10:$E$44"),INDIRECT("'"&F$4&"'!$b$10:$b$44"))," ")} | G39: {=_xlfn.IFNA(_xlfn.XLOOKUP($A39,INDIRECT("'"&G$4&"'!$E$10:$E$44"),INDIRECT("'"&G$4&"'!$b$10:$b$44"))," ")} | H39: {=_xlfn.IFNA(_xlfn.XLOOKUP($A39,INDIRECT("'"&H$4&"'!$E$10:$E$44"),INDIRECT("'"&H$4&"'!$b$10:$b$44"))," ")} | I39: {=_xlfn.IFNA(_xlfn.XLOOKUP($A39,INDIRECT("'"&I$4&"'!$E$10:$E$44"),INDIRECT("'"&I$4&"'!$b$10:$b$44"))," ")} | ... Q39: {=_xlfn.IFNA(_xlfn.XLOOKUP($A39,INDIRECT("'"&Q$4&"'!$E$10:$E$44"),INDIRECT("'"&Q$4&"'!$b$10:$b$44"))," ")} | T39: =SUM(B39:K39) | U39: =IFERROR(AVERAGEIF(B39:Q39,">=0"),0) | V39: =IFERROR(MAX(B39:Q39),0) | W39: =IFERROR(_xlfn.MINIFS(B39:Q39,B39:Q39,">0"),0) | X39: =RANK(T39,$T$5:$T$39)+COUNTIF($T$5:T39,T39)-1 | Y39: {=IFERROR(T39/SUMPRODUCT(($B39:$C39<>"")*$B$3:$C$3),0)}

Sheet Winnings
A1: $$$ WINNINGS
B3: Buy in $40
A4: Player | B4: Week 1 | C4: Week 2 | D4: Week 3 | E4: Week 4 | F4: Week 5 | G4: Week 6 | H4: Week 7 | I4: Week 8 | J4: Week 9 | K4: Week 10 | L4: Week 11 | M4: Week 12 | N4: Week 13 | O4: Week 14 | P4: Week 15 | Q4: Week 16 | R4: Week 17 | S4: Week 18 | T4: Winning | U4: Total | V4: Avg | W4: Best
A5: Bob h | B5: {=_xlfn.IFNA(_xlfn.XLOOKUP($A5,INDIRECT("'"&B$4&"'!$E$10:$E$44"),INDIRECT("'"&B$4&"'!$A$10:$A$44"))," ")} | C5: {=_xlfn.IFNA(_xlfn.XLOOKUP($A5,INDIRECT("'"&C$4&"'!$E$10:$E$44"),INDIRECT("'"&C$4&"'!$A$10:$A$44"))," ")} | D5: {=_xlfn.IFNA(_xlfn.XLOOKUP($A5,INDIRECT("'"&D$4&"'!$E$10:$E$44"),INDIRECT("'"&D$4&"'!$A$10:$A$44"))," ")} | E5: {=_xlfn.IFNA(_xlfn.XLOOKUP($A5,INDIRECT("'"&E$4&"'!$E$10:$E$44"),INDIRECT("'"&E$4&"'!$A$10:$A$44"))," ")} | F5: {=_xlfn.IFNA(_xlfn.XLOOKUP($A5,INDIRECT("'"&F$4&"'!$E$10:$E$44"),INDIRECT("'"&F$4&"'!$A$10:$A$44"))," ")} | G5: {=_xlfn.IFNA(_xlfn.XLOOKUP($A5,INDIRECT("'"&G$4&"'!$E$10:$E$44"),INDIRECT("'"&G$4&"'!$A$10:$A$44"))," ")} | H5: {=_xlfn.IFNA(_xlfn.XLOOKUP($A5,INDIRECT("'"&H$4&"'!$E$10:$E$44"),INDIRECT("'"&H$4&"'!$A$10:$A$44"))," ")} | I5: {=_xlfn.IFNA(_xlfn.XLOOKUP($A5,INDIRECT("'"&I$4&"'!$E$10:$E$44"),INDIRECT("'"&I$4&"'!$A$10:$A$44"))," ")} | ... S5: {=_xlfn.IFNA(_xlfn.XLOOKUP($A5,INDIRECT("'"&S$4&"'!$E$10:$E$44"),INDIRECT("'"&S$4&"'!$A$10:$A$44"))," ")} | T5: =SUM(Table5[[#This Row],[Week 1]:[Week 18]]) | U5: =SUM(B5:S5)-40 | V5: =IFERROR(SUM(B5:S5)/COUNT(B5:S5),0) | W5: =IFERROR(MAX(B5:S5),0)
A6: Brick_Hauss | B6: {=_xlfn.IFNA(_xlfn.XLOOKUP($A6,INDIRECT("'"&B$4&"'!$E$10:$E$44"),INDIRECT("'"&B$4&"'!$A$10:$A$44"))," ")} | C6: {=_xlfn.IFNA(_xlfn.XLOOKUP($A6,INDIRECT("'"&C$4&"'!$E$10:$E$44"),INDIRECT("'"&C$4&"'!$A$10:$A$44"))," ")} | D6: {=_xlfn.IFNA(_xlfn.XLOOKUP($A6,INDIRECT("'"&D$4&"'!$E$10:$E$44"),INDIRECT("'"&D$4&"'!$A$10:$A$44"))," ")} | E6: {=_xlfn.IFNA(_xlfn.XLOOKUP($A6,INDIRECT("'"&E$4&"'!$E$10:$E$44"),INDIRECT("'"&E$4&"'!$A$10:$A$44"))," ")} | F6: {=_xlfn.IFNA(_xlfn.XLOOKUP($A6,INDIRECT("'"&F$4&"'!$E$10:$E$44"),INDIRECT("'"&F$4&"'!$A$10:$A$44"))," ")} | G6: {=_xlfn.IFNA(_xlfn.XLOOKUP($A6,INDIRECT("'"&G$4&"'!$E$10:$E$44"),INDIRECT("'"&G$4&"'!$A$10:$A$44"))," ")} | H6: {=_xlfn.IFNA(_xlfn.XLOOKUP($A6,INDIRECT("'"&H$4&"'!$E$10:$E$44"),INDIRECT("'"&H$4&"'!$A$10:$A$44"))," ")} | I6: {=_xlfn.IFNA(_xlfn.XLOOKUP($A6,INDIRECT("'"&I$4&"'!$E$10:$E$44"),INDIRECT("'"&I$4&"'!$A$10:$A$44"))," ")} | ... S6: {=_xlfn.IFNA(_xlfn.XLOOKUP($A6,INDIRECT("'"&S$4&"'!$E$10:$E$44"),INDIRECT("'"&S$4&"'!$A$10:$A$44"))," ")} | T6: =SUM(Table5[[#This Row],[Week 1]:[Week 18]]) | U6: =SUM(B6:S6)-40 | V6: =IFERROR(SUM(B6:S6)/COUNT(B6:S6),0) | W6: =IFERROR(MAX(B6:S6),0)
A7: CraneGuy936 | B7: {=_xlfn.IFNA(_xlfn.XLOOKUP($A7,INDIRECT("'"&B$4&"'!$E$10:$E$44"),INDIRECT("'"&B$4&"'!$A$10:$A$44"))," ")} | C7: {=_xlfn.IFNA(_xlfn.XLOOKUP($A7,INDIRECT("'"&C$4&"'!$E$10:$E$44"),INDIRECT("'"&C$4&"'!$A$10:$A$44"))," ")} | D7: {=_xlfn.IFNA(_xlfn.XLOOKUP($A7,INDIRECT("'"&D$4&"'!$E$10:$E$44"),INDIRECT("'"&D$4&"'!$A$10:$A$44"))," ")} | E7: {=_xlfn.IFNA(_xlfn.XLOOKUP($A7,INDIRECT("'"&E$4&"'!$E$10:$E$44"),INDIRECT("'"&E$4&"'!$A$10:$A$44"))," ")} | F7: {=_xlfn.IFNA(_xlfn.XLOOKUP($A7,INDIRECT("'"&F$4&"'!$E$10:$E$44"),INDIRECT("'"&F$4&"'!$A$10:$A$44"))," ")} | G7: {=_xlfn.IFNA(_xlfn.XLOOKUP($A7,INDIRECT("'"&G$4&"'!$E$10:$E$44"),INDIRECT("'"&G$4&"'!$A$10:$A$44"))," ")} | H7: {=_xlfn.IFNA(_xlfn.XLOOKUP($A7,INDIRECT("'"&H$4&"'!$E$10:$E$44"),INDIRECT("'"&H$4&"'!$A$10:$A$44"))," ")} | I7: {=_xlfn.IFNA(_xlfn.XLOOKUP($A7,INDIRECT("'"&I$4&"'!$E$10:$E$44"),INDIRECT("'"&I$4&"'!$A$10:$A$44"))," ")} | ... S7: {=_xlfn.IFNA(_xlfn.XLOOKUP($A7,INDIRECT("'"&S$4&"'!$E$10:$E$44"),INDIRECT("'"&S$4&"'!$A$10:$A$44"))," ")} | T7: =SUM(Table5[[#This Row],[Week 1]:[Week 18]]) | U7: =SUM(B7:S7)-40 | V7: =IFERROR(SUM(B7:S7)/COUNT(B7:S7),0) | W7: =IFERROR(MAX(B7:S7),0)
A8: cuetop | B8: {=_xlfn.IFNA(_xlfn.XLOOKUP($A8,INDIRECT("'"&B$4&"'!$E$10:$E$44"),INDIRECT("'"&B$4&"'!$A$10:$A$44"))," ")} | C8: {=_xlfn.IFNA(_xlfn.XLOOKUP($A8,INDIRECT("'"&C$4&"'!$E$10:$E$44"),INDIRECT("'"&C$4&"'!$A$10:$A$44"))," ")} | D8: {=_xlfn.IFNA(_xlfn.XLOOKUP($A8,INDIRECT("'"&D$4&"'!$E$10:$E$44"),INDIRECT("'"&D$4&"'!$A$10:$A$44"))," ")} | E8: {=_xlfn.IFNA(_xlfn.XLOOKUP($A8,INDIRECT("'"&E$4&"'!$E$10:$E$44"),INDIRECT("'"&E$4&"'!$A$10:$A$44"))," ")} | F8: {=_xlfn.IFNA(_xlfn.XLOOKUP($A8,INDIRECT("'"&F$4&"'!$E$10:$E$44"),INDIRECT("'"&F$4&"'!$A$10:$A$44"))," ")} | G8: {=_xlfn.IFNA(_xlfn.XLOOKUP($A8,INDIRECT("'"&G$4&"'!$E$10:$E$44"),INDIRECT("'"&G$4&"'!$A$10:$A$44"))," ")} | H8: {=_xlfn.IFNA(_xlfn.XLOOKUP($A8,INDIRECT("'"&H$4&"'!$E$10:$E$44"),INDIRECT("'"&H$4&"'!$A$10:$A$44"))," ")} | I8: {=_xlfn.IFNA(_xlfn.XLOOKUP($A8,INDIRECT("'"&I$4&"'!$E$10:$E$44"),INDIRECT("'"&I$4&"'!$A$10:$A$44"))," ")} | ... S8: {=_xlfn.IFNA(_xlfn.XLOOKUP($A8,INDIRECT("'"&S$4&"'!$E$10:$E$44"),INDIRECT("'"&S$4&"'!$A$10:$A$44"))," ")} | T8: =SUM(Table5[[#This Row],[Week 1]:[Week 18]]) | U8: =SUM(B8:S8)-40 | V8: =IFERROR(SUM(B8:S8)/COUNT(B8:S8),0) | W8: =IFERROR(MAX(B8:S8),0)
A9: Ddupuy | B9: {=_xlfn.IFNA(_xlfn.XLOOKUP($A9,INDIRECT("'"&B$4&"'!$E$10:$E$44"),INDIRECT("'"&B$4&"'!$A$10:$A$44"))," ")} | C9: {=_xlfn.IFNA(_xlfn.XLOOKUP($A9,INDIRECT("'"&C$4&"'!$E$10:$E$44"),INDIRECT("'"&C$4&"'!$A$10:$A$44"))," ")} | D9: {=_xlfn.IFNA(_xlfn.XLOOKUP($A9,INDIRECT("'"&D$4&"'!$E$10:$E$44"),INDIRECT("'"&D$4&"'!$A$10:$A$44"))," ")} | E9: {=_xlfn.IFNA(_xlfn.XLOOKUP($A9,INDIRECT("'"&E$4&"'!$E$10:$E$44"),INDIRECT("'"&E$4&"'!$A$10:$A$44"))," ")} | F9: {=_xlfn.IFNA(_xlfn.XLOOKUP($A9,INDIRECT("'"&F$4&"'!$E$10:$E$44"),INDIRECT("'"&F$4&"'!$A$10:$A$44"))," ")} | G9: {=_xlfn.IFNA(_xlfn.XLOOKUP($A9,INDIRECT("'"&G$4&"'!$E$10:$E$44"),INDIRECT("'"&G$4&"'!$A$10:$A$44"))," ")} | H9: {=_xlfn.IFNA(_xlfn.XLOOKUP($A9,INDIRECT("'"&H$4&"'!$E$10:$E$44"),INDIRECT("'"&H$4&"'!$A$10:$A$44"))," ")} | I9: {=_xlfn.IFNA(_xlfn.XLOOKUP($A9,INDIRECT("'"&I$4&"'!$E$10:$E$44"),INDIRECT("'"&I$4&"'!$A$10:$A$44"))," ")} | ... S9: {=_xlfn.IFNA(_xlfn.XLOOKUP($A9,INDIRECT("'"&S$4&"'!$E$10:$E$44"),INDIRECT("'"&S$4&"'!$A$10:$A$44"))," ")} | T9: =SUM(Table5[[#This Row],[Week 1]:[Week 18]]) | U9: =SUM(B9:S9)-40 | V9: =IFERROR(SUM(B9:S9)/COUNT(B9:S9),0) | W9: =IFERROR(MAX(B9:S9),0)
A10: Debe | B10: {=_xlfn.IFNA(_xlfn.XLOOKUP($A10,INDIRECT("'"&B$4&"'!$E$10:$E$44"),INDIRECT("'"&B$4&"'!$A$10:$A$44"))," ")} | C10: {=_xlfn.IFNA(_xlfn.XLOOKUP($A10,INDIRECT("'"&C$4&"'!$E$10:$E$44"),INDIRECT("'"&C$4&"'!$A$10:$A$44"))," ")} | D10: {=_xlfn.IFNA(_xlfn.XLOOKUP($A10,INDIRECT("'"&D$4&"'!$E$10:$E$44"),INDIRECT("'"&D$4&"'!$A$10:$A$44"))," ")} | E10: {=_xlfn.IFNA(_xlfn.XLOOKUP($A10,INDIRECT("'"&E$4&"'!$E$10:$E$44"),INDIRECT("'"&E$4&"'!$A$10:$A$44"))," ")} | F10: {=_xlfn.IFNA(_xlfn.XLOOKUP($A10,INDIRECT("'"&F$4&"'!$E$10:$E$44"),INDIRECT("'"&F$4&"'!$A$10:$A$44"))," ")} | G10: {=_xlfn.IFNA(_xlfn.XLOOKUP($A10,INDIRECT("'"&G$4&"'!$E$10:$E$44"),INDIRECT("'"&G$4&"'!$A$10:$A$44"))," ")} | H10: {=_xlfn.IFNA(_xlfn.XLOOKUP($A10,INDIRECT("'"&H$4&"'!$E$10:$E$44"),INDIRECT("'"&H$4&"'!$A$10:$A$44"))," ")} | I10: {=_xlfn.IFNA(_xlfn.XLOOKUP($A10,INDIRECT("'"&I$4&"'!$E$10:$E$44"),INDIRECT("'"&I$4&"'!$A$10:$A$44"))," ")} | ... S10: {=_xlfn.IFNA(_xlfn.XLOOKUP($A10,INDIRECT("'"&S$4&"'!$E$10:$E$44"),INDIRECT("'"&S$4&"'!$A$10:$A$44"))," ")} | T10: =SUM(Table5[[#This Row],[Week 1]:[Week 18]]) | U10: =SUM(B10:S10)-40 | V10: =IFERROR(SUM(B10:S10)/COUNT(B10:S10),0) | W10: =IFERROR(MAX(B10:S10),0)
A11: DPSOG | B11: {=_xlfn.IFNA(_xlfn.XLOOKUP($A11,INDIRECT("'"&B$4&"'!$E$10:$E$44"),INDIRECT("'"&B$4&"'!$A$10:$A$44"))," ")} | C11: {=_xlfn.IFNA(_xlfn.XLOOKUP($A11,INDIRECT("'"&C$4&"'!$E$10:$E$44"),INDIRECT("'"&C$4&"'!$A$10:$A$44"))," ")} | D11: {=_xlfn.IFNA(_xlfn.XLOOKUP($A11,INDIRECT("'"&D$4&"'!$E$10:$E$44"),INDIRECT("'"&D$4&"'!$A$10:$A$44"))," ")} | E11: {=_xlfn.IFNA(_xlfn.XLOOKUP($A11,INDIRECT("'"&E$4&"'!$E$10:$E$44"),INDIRECT("'"&E$4&"'!$A$10:$A$44"))," ")} | F11: {=_xlfn.IFNA(_xlfn.XLOOKUP($A11,INDIRECT("'"&F$4&"'!$E$10:$E$44"),INDIRECT("'"&F$4&"'!$A$10:$A$44"))," ")} | G11: {=_xlfn.IFNA(_xlfn.XLOOKUP($A11,INDIRECT("'"&G$4&"'!$E$10:$E$44"),INDIRECT("'"&G$4&"'!$A$10:$A$44"))," ")} | H11: {=_xlfn.IFNA(_xlfn.XLOOKUP($A11,INDIRECT("'"&H$4&"'!$E$10:$E$44"),INDIRECT("'"&H$4&"'!$A$10:$A$44"))," ")} | I11: {=_xlfn.IFNA(_xlfn.XLOOKUP($A11,INDIRECT("'"&I$4&"'!$E$10:$E$44"),INDIRECT("'"&I$4&"'!$A$10:$A$44"))," ")} | ... S11: {=_xlfn.IFNA(_xlfn.XLOOKUP($A11,INDIRECT("'"&S$4&"'!$E$10:$E$44"),INDIRECT("'"&S$4&"'!$A$10:$A$44"))," ")} | T11: =SUM(Table5[[#This Row],[Week 1]:[Week 18]]) | U11: =SUM(B11:S11)-40 | V11: =IFERROR(SUM(B11:S11)/COUNT(B11:S11),0) | W11: =IFERROR(MAX(B11:S11),0)
A12: FMF Doc | B12: {=_xlfn.IFNA(_xlfn.XLOOKUP($A12,INDIRECT("'"&B$4&"'!$E$10:$E$44"),INDIRECT("'"&B$4&"'!$A$10:$A$44"))," ")} | C12: {=_xlfn.IFNA(_xlfn.XLOOKUP($A12,INDIRECT("'"&C$4&"'!$E$10:$E$44"),INDIRECT("'"&C$4&"'!$A$10:$A$44"))," ")} | D12: {=_xlfn.IFNA(_xlfn.XLOOKUP($A12,INDIRECT("'"&D$4&"'!$E$10:$E$44"),INDIRECT("'"&D$4&"'!$A$10:$A$44"))," ")} | E12: {=_xlfn.IFNA(_xlfn.XLOOKUP($A12,INDIRECT("'"&E$4&"'!$E$10:$E$44"),INDIRECT("'"&E$4&"'!$A$10:$A$44"))," ")} | F12: {=_xlfn.IFNA(_xlfn.XLOOKUP($A12,INDIRECT("'"&F$4&"'!$E$10:$E$44"),INDIRECT("'"&F$4&"'!$A$10:$A$44"))," ")} | G12: {=_xlfn.IFNA(_xlfn.XLOOKUP($A12,INDIRECT("'"&G$4&"'!$E$10:$E$44"),INDIRECT("'"&G$4&"'!$A$10:$A$44"))," ")} | H12: {=_xlfn.IFNA(_xlfn.XLOOKUP($A12,INDIRECT("'"&H$4&"'!$E$10:$E$44"),INDIRECT("'"&H$4&"'!$A$10:$A$44"))," ")} | I12: {=_xlfn.IFNA(_xlfn.XLOOKUP($A12,INDIRECT("'"&I$4&"'!$E$10:$E$44"),INDIRECT("'"&I$4&"'!$A$10:$A$44"))," ")} | ... S12: {=_xlfn.IFNA(_xlfn.XLOOKUP($A12,INDIRECT("'"&S$4&"'!$E$10:$E$44"),INDIRECT("'"&S$4&"'!$A$10:$A$44"))," ")} | T12: =SUM(Table5[[#This Row],[Week 1]:[Week 18]]) | U12: =SUM(B12:S12)-40 | V12: =IFERROR(SUM(B12:S12)/COUNT(B12:S12),0) | W12: =IFERROR(MAX(B12:S12),0)
A13: Frankethetank | B13: {=_xlfn.IFNA(_xlfn.XLOOKUP($A13,INDIRECT("'"&B$4&"'!$E$10:$E$44"),INDIRECT("'"&B$4&"'!$A$10:$A$44"))," ")} | C13: {=_xlfn.IFNA(_xlfn.XLOOKUP($A13,INDIRECT("'"&C$4&"'!$E$10:$E$44"),INDIRECT("'"&C$4&"'!$A$10:$A$44"))," ")} | D13: {=_xlfn.IFNA(_xlfn.XLOOKUP($A13,INDIRECT("'"&D$4&"'!$E$10:$E$44"),INDIRECT("'"&D$4&"'!$A$10:$A$44"))," ")} | E13: {=_xlfn.IFNA(_xlfn.XLOOKUP($A13,INDIRECT("'"&E$4&"'!$E$10:$E$44"),INDIRECT("'"&E$4&"'!$A$10:$A$44"))," ")} | F13: {=_xlfn.IFNA(_xlfn.XLOOKUP($A13,INDIRECT("'"&F$4&"'!$E$10:$E$44"),INDIRECT("'"&F$4&"'!$A$10:$A$44"))," ")} | G13: {=_xlfn.IFNA(_xlfn.XLOOKUP($A13,INDIRECT("'"&G$4&"'!$E$10:$E$44"),INDIRECT("'"&G$4&"'!$A$10:$A$44"))," ")} | H13: {=_xlfn.IFNA(_xlfn.XLOOKUP($A13,INDIRECT("'"&H$4&"'!$E$10:$E$44"),INDIRECT("'"&H$4&"'!$A$10:$A$44"))," ")} | I13: {=_xlfn.IFNA(_xlfn.XLOOKUP($A13,INDIRECT("'"&I$4&"'!$E$10:$E$44"),INDIRECT("'"&I$4&"'!$A$10:$A$44"))," ")} | ... S13: {=_xlfn.IFNA(_xlfn.XLOOKUP($A13,INDIRECT("'"&S$4&"'!$E$10:$E$44"),INDIRECT("'"&S$4&"'!$A$10:$A$44"))," ")} | T13: =SUM(Table5[[#This Row],[Week 1]:[Week 18]]) | U13: =SUM(B13:S13)-40 | V13: =IFERROR(SUM(B13:S13)/COUNT(B13:S13),0) | W13: =IFERROR(MAX(B13:S13),0)
A14: Gr8granpa | B14: {=_xlfn.IFNA(_xlfn.XLOOKUP($A14,INDIRECT("'"&B$4&"'!$E$10:$E$44"),INDIRECT("'"&B$4&"'!$A$10:$A$44"))," ")} | C14: {=_xlfn.IFNA(_xlfn.XLOOKUP($A14,INDIRECT("'"&C$4&"'!$E$10:$E$44"),INDIRECT("'"&C$4&"'!$A$10:$A$44"))," ")} | D14: {=_xlfn.IFNA(_xlfn.XLOOKUP($A14,INDIRECT("'"&D$4&"'!$E$10:$E$44"),INDIRECT("'"&D$4&"'!$A$10:$A$44"))," ")} | E14: {=_xlfn.IFNA(_xlfn.XLOOKUP($A14,INDIRECT("'"&E$4&"'!$E$10:$E$44"),INDIRECT("'"&E$4&"'!$A$10:$A$44"))," ")} | F14: {=_xlfn.IFNA(_xlfn.XLOOKUP($A14,INDIRECT("'"&F$4&"'!$E$10:$E$44"),INDIRECT("'"&F$4&"'!$A$10:$A$44"))," ")} | G14: {=_xlfn.IFNA(_xlfn.XLOOKUP($A14,INDIRECT("'"&G$4&"'!$E$10:$E$44"),INDIRECT("'"&G$4&"'!$A$10:$A$44"))," ")} | H14: {=_xlfn.IFNA(_xlfn.XLOOKUP($A14,INDIRECT("'"&H$4&"'!$E$10:$E$44"),INDIRECT("'"&H$4&"'!$A$10:$A$44"))," ")} | I14: {=_xlfn.IFNA(_xlfn.XLOOKUP($A14,INDIRECT("'"&I$4&"'!$E$10:$E$44"),INDIRECT("'"&I$4&"'!$A$10:$A$44"))," ")} | ... S14: {=_xlfn.IFNA(_xlfn.XLOOKUP($A14,INDIRECT("'"&S$4&"'!$E$10:$E$44"),INDIRECT("'"&S$4&"'!$A$10:$A$44"))," ")} | T14: =SUM(Table5[[#This Row],[Week 1]:[Week 18]]) | U14: =SUM(B14:S14)-40 | V14: =IFERROR(SUM(B14:S14)/COUNT(B14:S14),0) | W14: =IFERROR(MAX(B14:S14),0)
A15: Ian | B15: {=_xlfn.IFNA(_xlfn.XLOOKUP($A15,INDIRECT("'"&B$4&"'!$E$10:$E$44"),INDIRECT("'"&B$4&"'!$A$10:$A$44"))," ")} | C15: {=_xlfn.IFNA(_xlfn.XLOOKUP($A15,INDIRECT("'"&C$4&"'!$E$10:$E$44"),INDIRECT("'"&C$4&"'!$A$10:$A$44"))," ")} | D15: {=_xlfn.IFNA(_xlfn.XLOOKUP($A15,INDIRECT("'"&D$4&"'!$E$10:$E$44"),INDIRECT("'"&D$4&"'!$A$10:$A$44"))," ")} | E15: {=_xlfn.IFNA(_xlfn.XLOOKUP($A15,INDIRECT("'"&E$4&"'!$E$10:$E$44"),INDIRECT("'"&E$4&"'!$A$10:$A$44"))," ")} | F15: {=_xlfn.IFNA(_xlfn.XLOOKUP($A15,INDIRECT("'"&F$4&"'!$E$10:$E$44"),INDIRECT("'"&F$4&"'!$A$10:$A$44"))," ")} | G15: {=_xlfn.IFNA(_xlfn.XLOOKUP($A15,INDIRECT("'"&G$4&"'!$E$10:$E$44"),INDIRECT("'"&G$4&"'!$A$10:$A$44"))," ")} | H15: {=_xlfn.IFNA(_xlfn.XLOOKUP($A15,INDIRECT("'"&H$4&"'!$E$10:$E$44"),INDIRECT("'"&H$4&"'!$A$10:$A$44"))," ")} | I15: {=_xlfn.IFNA(_xlfn.XLOOKUP($A15,INDIRECT("'"&I$4&"'!$E$10:$E$44"),INDIRECT("'"&I$4&"'!$A$10:$A$44"))," ")} | ... S15: {=_xlfn.IFNA(_xlfn.XLOOKUP($A15,INDIRECT("'"&S$4&"'!$E$10:$E$44"),INDIRECT("'"&S$4&"'!$A$10:$A$44"))," ")} | T15: =SUM(Table5[[#This Row],[Week 1]:[Week 18]]) | U15: =SUM(B15:S15)-40 | V15: =IFERROR(SUM(B15:S15)/COUNT(B15:S15),0) | W15: =IFERROR(MAX(B15:S15),0)
A16: Jim T | B16: {=_xlfn.IFNA(_xlfn.XLOOKUP($A16,INDIRECT("'"&B$4&"'!$E$10:$E$44"),INDIRECT("'"&B$4&"'!$A$10:$A$44"))," ")} | C16: {=_xlfn.IFNA(_xlfn.XLOOKUP($A16,INDIRECT("'"&C$4&"'!$E$10:$E$44"),INDIRECT("'"&C$4&"'!$A$10:$A$44"))," ")} | D16: {=_xlfn.IFNA(_xlfn.XLOOKUP($A16,INDIRECT("'"&D$4&"'!$E$10:$E$44"),INDIRECT("'"&D$4&"'!$A$10:$A$44"))," ")} | E16: {=_xlfn.IFNA(_xlfn.XLOOKUP($A16,INDIRECT("'"&E$4&"'!$E$10:$E$44"),INDIRECT("'"&E$4&"'!$A$10:$A$44"))," ")} | F16: {=_xlfn.IFNA(_xlfn.XLOOKUP($A16,INDIRECT("'"&F$4&"'!$E$10:$E$44"),INDIRECT("'"&F$4&"'!$A$10:$A$44"))," ")} | G16: {=_xlfn.IFNA(_xlfn.XLOOKUP($A16,INDIRECT("'"&G$4&"'!$E$10:$E$44"),INDIRECT("'"&G$4&"'!$A$10:$A$44"))," ")} | H16: {=_xlfn.IFNA(_xlfn.XLOOKUP($A16,INDIRECT("'"&H$4&"'!$E$10:$E$44"),INDIRECT("'"&H$4&"'!$A$10:$A$44"))," ")} | I16: {=_xlfn.IFNA(_xlfn.XLOOKUP($A16,INDIRECT("'"&I$4&"'!$E$10:$E$44"),INDIRECT("'"&I$4&"'!$A$10:$A$44"))," ")} | ... S16: {=_xlfn.IFNA(_xlfn.XLOOKUP($A16,INDIRECT("'"&S$4&"'!$E$10:$E$44"),INDIRECT("'"&S$4&"'!$A$10:$A$44"))," ")} | T16: =SUM(Table5[[#This Row],[Week 1]:[Week 18]]) | U16: =SUM(B16:S16)-40 | V16: =IFERROR(SUM(B16:S16)/COUNT(B16:S16),0) | W16: =IFERROR(MAX(B16:S16),0)
